[2025-12-19 10:21:20] [INFO] [RUN] Using dataset: datasource/9_2.json
[2025-12-19 10:21:20] [INFO] [RUN] Initializing 9 PMs
[2025-12-19 10:21:20] [INFO] [PM] Init PM PM_0 | CPU_CAP=128 | MEM_CAP=2400
[2025-12-19 10:21:20] [INFO] [STATE] PM added: PM_0
[2025-12-19 10:21:20] [INFO] [PM] Init PM PM_1 | CPU_CAP=128 | MEM_CAP=2400
[2025-12-19 10:21:20] [INFO] [STATE] PM added: PM_1
[2025-12-19 10:21:20] [INFO] [PM] Init PM PM_2 | CPU_CAP=128 | MEM_CAP=2400
[2025-12-19 10:21:20] [INFO] [STATE] PM added: PM_2
[2025-12-19 10:21:20] [INFO] [PM] Init PM PM_3 | CPU_CAP=128 | MEM_CAP=2400
[2025-12-19 10:21:20] [INFO] [STATE] PM added: PM_3
[2025-12-19 10:21:20] [INFO] [PM] Init PM PM_4 | CPU_CAP=128 | MEM_CAP=2400
[2025-12-19 10:21:20] [INFO] [STATE] PM added: PM_4
[2025-12-19 10:21:20] [INFO] [PM] Init PM PM_5 | CPU_CAP=128 | MEM_CAP=2400
[2025-12-19 10:21:20] [INFO] [STATE] PM added: PM_5
[2025-12-19 10:21:20] [INFO] [PM] Init PM PM_6 | CPU_CAP=128 | MEM_CAP=2400
[2025-12-19 10:21:20] [INFO] [STATE] PM added: PM_6
[2025-12-19 10:21:20] [INFO] [PM] Init PM PM_7 | CPU_CAP=128 | MEM_CAP=2400
[2025-12-19 10:21:20] [INFO] [STATE] PM added: PM_7
[2025-12-19 10:21:20] [INFO] [PM] Init PM PM_8 | CPU_CAP=128 | MEM_CAP=2400
[2025-12-19 10:21:20] [INFO] [STATE] PM added: PM_8
[2025-12-19 10:21:20] [INFO] [ONLINE_TRACE] Loaded online trace from datasource/9_2.json
[2025-12-19 10:21:20] [INFO] [ONLINE_TRACE] Number of PMs = 9
[2025-12-19 10:21:20] [INFO] [ONLINE_TRACE] Generated 900 events from trace
[2025-12-19 10:21:20] [INFO] [SIMULATOR] Simulation started
[2025-12-19 10:21:20] [INFO] [VM_EVENT] VM vm_0 created (pending) at t=96
[2025-12-19 10:21:20] [INFO] [VM_EVENT] VM vm_1 created (pending) at t=96
[2025-12-19 10:21:20] [INFO] [VM_EVENT] VM vm_2 created (pending) at t=96
[2025-12-19 10:21:20] [INFO] [VM_EVENT] VM vm_3 created (pending) at t=96
[2025-12-19 10:21:20] [INFO] [VM_EVENT] VM vm_4 created (pending) at t=96
[2025-12-19 10:21:20] [INFO] [VM_EVENT] VM vm_5 created (pending) at t=96
[2025-12-19 10:21:20] [INFO] [VM_EVENT] VM vm_6 created (pending) at t=96
[2025-12-19 10:21:20] [INFO] [VM_EVENT] VM vm_7 created (pending) at t=96
[2025-12-19 10:21:20] [INFO] [VM_EVENT] VM vm_8 created (pending) at t=96
[2025-12-19 10:21:20] [INFO] [VM_EVENT] VM vm_9 created (pending) at t=96
[2025-12-19 10:21:20] [INFO] [VM_EVENT] VM vm_10 created (pending) at t=96
[2025-12-19 10:21:20] [INFO] [VM_EVENT] VM vm_11 created (pending) at t=96
[2025-12-19 10:21:20] [INFO] [VM_EVENT] VM vm_12 created (pending) at t=96
[2025-12-19 10:21:20] [INFO] [VM_EVENT] VM vm_13 created (pending) at t=96
[2025-12-19 10:21:20] [INFO] [VM_EVENT] VM vm_14 created (pending) at t=96
[2025-12-19 10:21:20] [INFO] [VM_EVENT] VM vm_15 created (pending) at t=96
[2025-12-19 10:21:20] [INFO] [VM_EVENT] VM vm_16 created (pending) at t=96
[2025-12-19 10:21:20] [INFO] [VM_EVENT] VM vm_17 created (pending) at t=96
[2025-12-19 10:21:20] [INFO] [VM_EVENT] VM vm_18 created (pending) at t=96
[2025-12-19 10:21:20] [INFO] [VM_EVENT] VM vm_19 created (pending) at t=96
[2025-12-19 10:21:20] [INFO] [VM_EVENT] VM vm_20 created (pending) at t=96
[2025-12-19 10:21:20] [INFO] [VM_EVENT] VM vm_21 created (pending) at t=96
[2025-12-19 10:21:20] [INFO] [SCHEDULER] FCFS embed VM vm_0 -> PM PM_3 at t=96
[2025-12-19 10:21:20] [INFO] [SCHEDULER] FCFS embed VM vm_1 -> PM PM_3 at t=96
[2025-12-19 10:21:20] [INFO] [SCHEDULER] FCFS embed VM vm_2 -> PM PM_3 at t=96
[2025-12-19 10:21:20] [INFO] [SCHEDULER] FCFS embed VM vm_3 -> PM PM_3 at t=96
[2025-12-19 10:21:20] [INFO] [SCHEDULER] FCFS embed VM vm_4 -> PM PM_3 at t=96
[2025-12-19 10:21:20] [INFO] [SCHEDULER] FCFS embed VM vm_5 -> PM PM_3 at t=96
[2025-12-19 10:21:20] [INFO] [SCHEDULER] FCFS embed VM vm_6 -> PM PM_3 at t=96
[2025-12-19 10:21:20] [INFO] [SCHEDULER] FCFS embed VM vm_7 -> PM PM_3 at t=96
[2025-12-19 10:21:20] [INFO] [SCHEDULER] FCFS embed VM vm_8 -> PM PM_3 at t=96
[2025-12-19 10:21:20] [INFO] [SCHEDULER] FCFS embed VM vm_9 -> PM PM_3 at t=96
[2025-12-19 10:21:20] [INFO] [SCHEDULER] FCFS embed VM vm_10 -> PM PM_3 at t=96
[2025-12-19 10:21:20] [INFO] [SCHEDULER] FCFS embed VM vm_11 -> PM PM_3 at t=96
[2025-12-19 10:21:20] [INFO] [SCHEDULER] FCFS embed VM vm_12 -> PM PM_3 at t=96
[2025-12-19 10:21:20] [INFO] [SCHEDULER] FCFS embed VM vm_13 -> PM PM_3 at t=96
[2025-12-19 10:21:20] [INFO] [SCHEDULER] FCFS embed VM vm_14 -> PM PM_3 at t=96
[2025-12-19 10:21:20] [INFO] [SCHEDULER] FCFS embed VM vm_15 -> PM PM_3 at t=96
[2025-12-19 10:21:20] [INFO] [SCHEDULER] FCFS embed VM vm_16 -> PM PM_3 at t=96
[2025-12-19 10:21:20] [INFO] [SCHEDULER] FCFS embed VM vm_17 -> PM PM_3 at t=96
[2025-12-19 10:21:20] [INFO] [SCHEDULER] FCFS embed VM vm_18 -> PM PM_3 at t=96
[2025-12-19 10:21:20] [INFO] [SCHEDULER] FCFS embed VM vm_19 -> PM PM_3 at t=96
[2025-12-19 10:21:20] [INFO] [SCHEDULER] FCFS embed VM vm_20 -> PM PM_3 at t=96
[2025-12-19 10:21:20] [INFO] [SCHEDULER] FCFS embed VM vm_21 -> PM PM_3 at t=96
[2025-12-19 10:21:20] [INFO] [STATE] VM vm_0 placed on PM PM_3
[2025-12-19 10:21:20] [INFO] [STATE] VM vm_1 placed on PM PM_3
[2025-12-19 10:21:20] [INFO] [STATE] VM vm_2 placed on PM PM_3
[2025-12-19 10:21:20] [INFO] [STATE] VM vm_3 placed on PM PM_3
[2025-12-19 10:21:20] [INFO] [STATE] VM vm_4 placed on PM PM_3
[2025-12-19 10:21:20] [INFO] [STATE] VM vm_5 placed on PM PM_3
[2025-12-19 10:21:20] [INFO] [STATE] VM vm_6 placed on PM PM_3
[2025-12-19 10:21:20] [INFO] [STATE] VM vm_7 placed on PM PM_3
[2025-12-19 10:21:20] [INFO] [STATE] VM vm_8 placed on PM PM_3
[2025-12-19 10:21:20] [INFO] [STATE] VM vm_9 placed on PM PM_3
[2025-12-19 10:21:20] [INFO] [STATE] VM vm_10 placed on PM PM_3
[2025-12-19 10:21:20] [INFO] [STATE] VM vm_11 placed on PM PM_3
[2025-12-19 10:21:20] [INFO] [STATE] VM vm_12 placed on PM PM_3
[2025-12-19 10:21:20] [INFO] [STATE] VM vm_13 placed on PM PM_3
[2025-12-19 10:21:20] [INFO] [STATE] VM vm_14 placed on PM PM_3
[2025-12-19 10:21:20] [INFO] [STATE] VM vm_15 placed on PM PM_3
[2025-12-19 10:21:20] [INFO] [STATE] VM vm_16 placed on PM PM_3
[2025-12-19 10:21:20] [INFO] [STATE] VM vm_17 placed on PM PM_3
[2025-12-19 10:21:20] [INFO] [STATE] VM vm_18 placed on PM PM_3
[2025-12-19 10:21:20] [INFO] [STATE] VM vm_19 placed on PM PM_3
[2025-12-19 10:21:20] [INFO] [STATE] VM vm_20 placed on PM PM_3
[2025-12-19 10:21:20] [INFO] [STATE] VM vm_21 placed on PM PM_3
[2025-12-19 10:21:20] [INFO] [VM_EVENT] VM vm_22 created (pending) at t=97
[2025-12-19 10:21:20] [INFO] [VM_EVENT] VM vm_23 created (pending) at t=97
[2025-12-19 10:21:20] [INFO] [VM_EVENT] VM vm_24 created (pending) at t=97
[2025-12-19 10:21:20] [INFO] [VM_EVENT] VM vm_25 created (pending) at t=97
[2025-12-19 10:21:20] [INFO] [VM_EVENT] VM vm_26 created (pending) at t=97
[2025-12-19 10:21:20] [INFO] [VM_EVENT] VM vm_27 created (pending) at t=97
[2025-12-19 10:21:20] [INFO] [VM_EVENT] VM vm_28 created (pending) at t=97
[2025-12-19 10:21:20] [INFO] [VM_EVENT] VM vm_29 created (pending) at t=97
[2025-12-19 10:21:20] [INFO] [VM_EVENT] VM vm_30 created (pending) at t=97
[2025-12-19 10:21:20] [INFO] [VM_EVENT] VM vm_31 created (pending) at t=97
[2025-12-19 10:21:20] [INFO] [VM_EVENT] VM vm_32 created (pending) at t=97
[2025-12-19 10:21:20] [INFO] [VM_EVENT] VM vm_33 created (pending) at t=97
[2025-12-19 10:21:20] [INFO] [VM_EVENT] VM vm_34 created (pending) at t=97
[2025-12-19 10:21:20] [INFO] [VM_EVENT] VM vm_35 created (pending) at t=97
[2025-12-19 10:21:20] [INFO] [VM_EVENT] VM vm_36 created (pending) at t=97
[2025-12-19 10:21:20] [INFO] [VM_EVENT] VM vm_37 created (pending) at t=97
[2025-12-19 10:21:20] [INFO] [VM_EVENT] VM vm_38 created (pending) at t=97
[2025-12-19 10:21:20] [INFO] [VM_EVENT] VM vm_39 created (pending) at t=97
[2025-12-19 10:21:20] [INFO] [VM_EVENT] VM vm_40 created (pending) at t=97
[2025-12-19 10:21:20] [INFO] [VM_EVENT] VM vm_41 created (pending) at t=97
[2025-12-19 10:21:20] [INFO] [VM_EVENT] VM vm_42 created (pending) at t=97
[2025-12-19 10:21:20] [INFO] [VM_EVENT] VM vm_43 created (pending) at t=97
[2025-12-19 10:21:20] [INFO] [SCHEDULER] FCFS embed VM vm_22 -> PM PM_1 at t=97
[2025-12-19 10:21:20] [INFO] [SCHEDULER] FCFS embed VM vm_23 -> PM PM_1 at t=97
[2025-12-19 10:21:20] [INFO] [SCHEDULER] FCFS embed VM vm_24 -> PM PM_1 at t=97
[2025-12-19 10:21:20] [INFO] [SCHEDULER] FCFS embed VM vm_25 -> PM PM_1 at t=97
[2025-12-19 10:21:20] [INFO] [SCHEDULER] FCFS embed VM vm_26 -> PM PM_1 at t=97
[2025-12-19 10:21:20] [INFO] [SCHEDULER] FCFS embed VM vm_27 -> PM PM_1 at t=97
[2025-12-19 10:21:20] [INFO] [SCHEDULER] FCFS embed VM vm_28 -> PM PM_1 at t=97
[2025-12-19 10:21:20] [INFO] [SCHEDULER] FCFS embed VM vm_29 -> PM PM_1 at t=97
[2025-12-19 10:21:20] [INFO] [SCHEDULER] FCFS embed VM vm_30 -> PM PM_1 at t=97
[2025-12-19 10:21:20] [INFO] [SCHEDULER] FCFS embed VM vm_31 -> PM PM_1 at t=97
[2025-12-19 10:21:20] [INFO] [SCHEDULER] FCFS embed VM vm_32 -> PM PM_1 at t=97
[2025-12-19 10:21:20] [INFO] [SCHEDULER] FCFS embed VM vm_33 -> PM PM_1 at t=97
[2025-12-19 10:21:20] [INFO] [SCHEDULER] FCFS embed VM vm_34 -> PM PM_1 at t=97
[2025-12-19 10:21:20] [INFO] [SCHEDULER] FCFS embed VM vm_35 -> PM PM_1 at t=97
[2025-12-19 10:21:20] [INFO] [SCHEDULER] FCFS embed VM vm_36 -> PM PM_1 at t=97
[2025-12-19 10:21:20] [INFO] [SCHEDULER] FCFS embed VM vm_37 -> PM PM_1 at t=97
[2025-12-19 10:21:20] [INFO] [SCHEDULER] FCFS embed VM vm_38 -> PM PM_1 at t=97
[2025-12-19 10:21:20] [INFO] [SCHEDULER] FCFS embed VM vm_39 -> PM PM_1 at t=97
[2025-12-19 10:21:20] [INFO] [SCHEDULER] FCFS embed VM vm_40 -> PM PM_1 at t=97
[2025-12-19 10:21:20] [INFO] [SCHEDULER] FCFS embed VM vm_41 -> PM PM_1 at t=97
[2025-12-19 10:21:20] [INFO] [SCHEDULER] FCFS embed VM vm_42 -> PM PM_1 at t=97
[2025-12-19 10:21:20] [INFO] [SCHEDULER] FCFS embed VM vm_43 -> PM PM_1 at t=97
[2025-12-19 10:21:20] [INFO] [STATE] VM vm_22 placed on PM PM_1
[2025-12-19 10:21:20] [INFO] [STATE] VM vm_23 placed on PM PM_1
[2025-12-19 10:21:20] [INFO] [STATE] VM vm_24 placed on PM PM_1
[2025-12-19 10:21:20] [INFO] [STATE] VM vm_25 placed on PM PM_1
[2025-12-19 10:21:20] [INFO] [STATE] VM vm_26 placed on PM PM_1
[2025-12-19 10:21:20] [INFO] [STATE] VM vm_27 placed on PM PM_1
[2025-12-19 10:21:20] [INFO] [STATE] VM vm_28 placed on PM PM_1
[2025-12-19 10:21:20] [INFO] [STATE] VM vm_29 placed on PM PM_1
[2025-12-19 10:21:20] [INFO] [STATE] VM vm_30 placed on PM PM_1
[2025-12-19 10:21:20] [INFO] [STATE] VM vm_31 placed on PM PM_1
[2025-12-19 10:21:20] [INFO] [STATE] VM vm_32 placed on PM PM_1
[2025-12-19 10:21:20] [INFO] [STATE] VM vm_33 placed on PM PM_1
[2025-12-19 10:21:20] [INFO] [STATE] VM vm_34 placed on PM PM_1
[2025-12-19 10:21:20] [INFO] [STATE] VM vm_35 placed on PM PM_1
[2025-12-19 10:21:20] [INFO] [STATE] VM vm_36 placed on PM PM_1
[2025-12-19 10:21:20] [INFO] [STATE] VM vm_37 placed on PM PM_1
[2025-12-19 10:21:20] [INFO] [STATE] VM vm_38 placed on PM PM_1
[2025-12-19 10:21:20] [INFO] [STATE] VM vm_39 placed on PM PM_1
[2025-12-19 10:21:20] [INFO] [STATE] VM vm_40 placed on PM PM_1
[2025-12-19 10:21:20] [INFO] [STATE] VM vm_41 placed on PM PM_1
[2025-12-19 10:21:20] [INFO] [STATE] VM vm_42 placed on PM PM_1
[2025-12-19 10:21:20] [INFO] [STATE] VM vm_43 placed on PM PM_1
[2025-12-19 10:21:20] [INFO] [VM_EVENT] VM vm_44 created (pending) at t=98
[2025-12-19 10:21:20] [INFO] [VM_EVENT] VM vm_45 created (pending) at t=98
[2025-12-19 10:21:20] [INFO] [VM_EVENT] VM vm_46 created (pending) at t=98
[2025-12-19 10:21:20] [INFO] [VM_EVENT] VM vm_47 created (pending) at t=98
[2025-12-19 10:21:20] [INFO] [VM_EVENT] VM vm_48 created (pending) at t=98
[2025-12-19 10:21:20] [INFO] [VM_EVENT] VM vm_49 created (pending) at t=98
[2025-12-19 10:21:20] [INFO] [VM_EVENT] VM vm_50 created (pending) at t=98
[2025-12-19 10:21:20] [INFO] [VM_EVENT] VM vm_51 created (pending) at t=98
[2025-12-19 10:21:20] [INFO] [VM_EVENT] VM vm_52 created (pending) at t=98
[2025-12-19 10:21:20] [INFO] [VM_EVENT] VM vm_53 created (pending) at t=98
[2025-12-19 10:21:20] [INFO] [VM_EVENT] VM vm_54 created (pending) at t=98
[2025-12-19 10:21:20] [INFO] [VM_EVENT] VM vm_55 created (pending) at t=98
[2025-12-19 10:21:20] [INFO] [VM_EVENT] VM vm_56 created (pending) at t=98
[2025-12-19 10:21:20] [INFO] [VM_EVENT] VM vm_57 created (pending) at t=98
[2025-12-19 10:21:20] [INFO] [VM_EVENT] VM vm_58 created (pending) at t=98
[2025-12-19 10:21:20] [INFO] [VM_EVENT] VM vm_59 created (pending) at t=98
[2025-12-19 10:21:20] [INFO] [VM_EVENT] VM vm_60 created (pending) at t=98
[2025-12-19 10:21:20] [INFO] [VM_EVENT] VM vm_61 created (pending) at t=98
[2025-12-19 10:21:20] [INFO] [VM_EVENT] VM vm_62 created (pending) at t=98
[2025-12-19 10:21:20] [INFO] [VM_EVENT] VM vm_63 created (pending) at t=98
[2025-12-19 10:21:20] [INFO] [VM_EVENT] VM vm_64 created (pending) at t=98
[2025-12-19 10:21:20] [INFO] [SCHEDULER] FCFS embed VM vm_44 -> PM PM_0 at t=98
[2025-12-19 10:21:20] [INFO] [SCHEDULER] FCFS embed VM vm_45 -> PM PM_0 at t=98
[2025-12-19 10:21:20] [INFO] [SCHEDULER] FCFS embed VM vm_46 -> PM PM_0 at t=98
[2025-12-19 10:21:20] [INFO] [SCHEDULER] FCFS embed VM vm_47 -> PM PM_0 at t=98
[2025-12-19 10:21:20] [INFO] [SCHEDULER] FCFS embed VM vm_48 -> PM PM_0 at t=98
[2025-12-19 10:21:20] [INFO] [SCHEDULER] FCFS embed VM vm_49 -> PM PM_0 at t=98
[2025-12-19 10:21:20] [INFO] [SCHEDULER] FCFS embed VM vm_50 -> PM PM_0 at t=98
[2025-12-19 10:21:20] [INFO] [SCHEDULER] FCFS embed VM vm_51 -> PM PM_0 at t=98
[2025-12-19 10:21:20] [INFO] [SCHEDULER] FCFS embed VM vm_52 -> PM PM_0 at t=98
[2025-12-19 10:21:20] [INFO] [SCHEDULER] FCFS embed VM vm_53 -> PM PM_0 at t=98
[2025-12-19 10:21:20] [INFO] [SCHEDULER] FCFS embed VM vm_54 -> PM PM_0 at t=98
[2025-12-19 10:21:20] [INFO] [SCHEDULER] FCFS embed VM vm_55 -> PM PM_0 at t=98
[2025-12-19 10:21:20] [INFO] [SCHEDULER] FCFS embed VM vm_56 -> PM PM_0 at t=98
[2025-12-19 10:21:20] [INFO] [SCHEDULER] FCFS embed VM vm_57 -> PM PM_0 at t=98
[2025-12-19 10:21:20] [INFO] [SCHEDULER] FCFS embed VM vm_58 -> PM PM_0 at t=98
[2025-12-19 10:21:20] [INFO] [SCHEDULER] FCFS embed VM vm_59 -> PM PM_0 at t=98
[2025-12-19 10:21:20] [INFO] [SCHEDULER] FCFS embed VM vm_60 -> PM PM_0 at t=98
[2025-12-19 10:21:20] [INFO] [SCHEDULER] FCFS embed VM vm_61 -> PM PM_0 at t=98
[2025-12-19 10:21:20] [INFO] [SCHEDULER] FCFS embed VM vm_62 -> PM PM_0 at t=98
[2025-12-19 10:21:20] [INFO] [SCHEDULER] FCFS embed VM vm_63 -> PM PM_0 at t=98
[2025-12-19 10:21:20] [INFO] [SCHEDULER] FCFS embed VM vm_64 -> PM PM_0 at t=98
[2025-12-19 10:21:20] [INFO] [STATE] VM vm_44 placed on PM PM_0
[2025-12-19 10:21:20] [INFO] [STATE] VM vm_45 placed on PM PM_0
[2025-12-19 10:21:20] [INFO] [STATE] VM vm_46 placed on PM PM_0
[2025-12-19 10:21:20] [INFO] [STATE] VM vm_47 placed on PM PM_0
[2025-12-19 10:21:20] [INFO] [STATE] VM vm_48 placed on PM PM_0
[2025-12-19 10:21:20] [INFO] [STATE] VM vm_49 placed on PM PM_0
[2025-12-19 10:21:20] [INFO] [STATE] VM vm_50 placed on PM PM_0
[2025-12-19 10:21:20] [INFO] [STATE] VM vm_51 placed on PM PM_0
[2025-12-19 10:21:20] [INFO] [STATE] VM vm_52 placed on PM PM_0
[2025-12-19 10:21:20] [INFO] [STATE] VM vm_53 placed on PM PM_0
[2025-12-19 10:21:20] [INFO] [STATE] VM vm_54 placed on PM PM_0
[2025-12-19 10:21:20] [INFO] [STATE] VM vm_55 placed on PM PM_0
[2025-12-19 10:21:20] [INFO] [STATE] VM vm_56 placed on PM PM_0
[2025-12-19 10:21:20] [INFO] [STATE] VM vm_57 placed on PM PM_0
[2025-12-19 10:21:20] [INFO] [STATE] VM vm_58 placed on PM PM_0
[2025-12-19 10:21:20] [INFO] [STATE] VM vm_59 placed on PM PM_0
[2025-12-19 10:21:20] [INFO] [STATE] VM vm_60 placed on PM PM_0
[2025-12-19 10:21:20] [INFO] [STATE] VM vm_61 placed on PM PM_0
[2025-12-19 10:21:20] [INFO] [STATE] VM vm_62 placed on PM PM_0
[2025-12-19 10:21:20] [INFO] [STATE] VM vm_63 placed on PM PM_0
[2025-12-19 10:21:20] [INFO] [STATE] VM vm_64 placed on PM PM_0
[2025-12-19 10:21:20] [INFO] [VM_EVENT] VM vm_65 created (pending) at t=99
[2025-12-19 10:21:20] [INFO] [VM_EVENT] VM vm_66 created (pending) at t=99
[2025-12-19 10:21:20] [INFO] [VM_EVENT] VM vm_67 created (pending) at t=99
[2025-12-19 10:21:20] [INFO] [VM_EVENT] VM vm_68 created (pending) at t=99
[2025-12-19 10:21:20] [INFO] [VM_EVENT] VM vm_69 created (pending) at t=99
[2025-12-19 10:21:20] [INFO] [VM_EVENT] VM vm_70 created (pending) at t=99
[2025-12-19 10:21:20] [INFO] [VM_EVENT] VM vm_71 created (pending) at t=99
[2025-12-19 10:21:20] [INFO] [VM_EVENT] VM vm_72 created (pending) at t=99
[2025-12-19 10:21:20] [INFO] [VM_EVENT] VM vm_73 created (pending) at t=99
[2025-12-19 10:21:20] [INFO] [VM_EVENT] VM vm_74 created (pending) at t=99
[2025-12-19 10:21:20] [INFO] [VM_EVENT] VM vm_75 created (pending) at t=99
[2025-12-19 10:21:20] [INFO] [VM_EVENT] VM vm_76 created (pending) at t=99
[2025-12-19 10:21:20] [INFO] [VM_EVENT] VM vm_77 created (pending) at t=99
[2025-12-19 10:21:20] [INFO] [VM_EVENT] VM vm_78 created (pending) at t=99
[2025-12-19 10:21:20] [INFO] [VM_EVENT] VM vm_79 created (pending) at t=99
[2025-12-19 10:21:20] [INFO] [VM_EVENT] VM vm_80 created (pending) at t=99
[2025-12-19 10:21:20] [INFO] [VM_EVENT] VM vm_81 created (pending) at t=99
[2025-12-19 10:21:20] [INFO] [VM_EVENT] VM vm_82 created (pending) at t=99
[2025-12-19 10:21:20] [INFO] [VM_EVENT] VM vm_83 created (pending) at t=99
[2025-12-19 10:21:20] [INFO] [VM_EVENT] VM vm_84 created (pending) at t=99
[2025-12-19 10:21:20] [INFO] [SCHEDULER] FCFS embed VM vm_65 -> PM PM_3 at t=99
[2025-12-19 10:21:20] [INFO] [SCHEDULER] FCFS embed VM vm_66 -> PM PM_3 at t=99
[2025-12-19 10:21:20] [INFO] [SCHEDULER] FCFS embed VM vm_67 -> PM PM_3 at t=99
[2025-12-19 10:21:20] [INFO] [SCHEDULER] FCFS embed VM vm_68 -> PM PM_3 at t=99
[2025-12-19 10:21:20] [INFO] [SCHEDULER] FCFS embed VM vm_69 -> PM PM_3 at t=99
[2025-12-19 10:21:20] [INFO] [SCHEDULER] FCFS embed VM vm_70 -> PM PM_3 at t=99
[2025-12-19 10:21:20] [INFO] [SCHEDULER] FCFS embed VM vm_71 -> PM PM_3 at t=99
[2025-12-19 10:21:20] [INFO] [SCHEDULER] FCFS embed VM vm_72 -> PM PM_3 at t=99
[2025-12-19 10:21:20] [INFO] [SCHEDULER] FCFS embed VM vm_73 -> PM PM_3 at t=99
[2025-12-19 10:21:20] [INFO] [SCHEDULER] FCFS embed VM vm_74 -> PM PM_3 at t=99
[2025-12-19 10:21:20] [INFO] [SCHEDULER] FCFS embed VM vm_75 -> PM PM_3 at t=99
[2025-12-19 10:21:20] [INFO] [SCHEDULER] FCFS embed VM vm_76 -> PM PM_3 at t=99
[2025-12-19 10:21:20] [INFO] [SCHEDULER] FCFS embed VM vm_77 -> PM PM_3 at t=99
[2025-12-19 10:21:20] [INFO] [SCHEDULER] FCFS embed VM vm_78 -> PM PM_3 at t=99
[2025-12-19 10:21:20] [INFO] [SCHEDULER] FCFS embed VM vm_79 -> PM PM_3 at t=99
[2025-12-19 10:21:20] [INFO] [SCHEDULER] FCFS embed VM vm_80 -> PM PM_3 at t=99
[2025-12-19 10:21:20] [INFO] [SCHEDULER] FCFS embed VM vm_81 -> PM PM_3 at t=99
[2025-12-19 10:21:20] [INFO] [SCHEDULER] FCFS embed VM vm_82 -> PM PM_3 at t=99
[2025-12-19 10:21:20] [INFO] [SCHEDULER] FCFS embed VM vm_83 -> PM PM_3 at t=99
[2025-12-19 10:21:20] [INFO] [SCHEDULER] FCFS embed VM vm_84 -> PM PM_3 at t=99
[2025-12-19 10:21:20] [INFO] [STATE] VM vm_65 placed on PM PM_3
[2025-12-19 10:21:20] [INFO] [STATE] VM vm_66 placed on PM PM_3
[2025-12-19 10:21:20] [INFO] [STATE] VM vm_67 placed on PM PM_3
[2025-12-19 10:21:20] [INFO] [STATE] VM vm_68 placed on PM PM_3
[2025-12-19 10:21:20] [INFO] [STATE] VM vm_69 placed on PM PM_3
[2025-12-19 10:21:20] [INFO] [STATE] VM vm_70 placed on PM PM_3
[2025-12-19 10:21:20] [INFO] [STATE] VM vm_71 placed on PM PM_3
[2025-12-19 10:21:20] [INFO] [STATE] VM vm_72 placed on PM PM_3
[2025-12-19 10:21:20] [INFO] [STATE] VM vm_73 placed on PM PM_3
[2025-12-19 10:21:20] [INFO] [STATE] VM vm_74 placed on PM PM_3
[2025-12-19 10:21:20] [INFO] [STATE] VM vm_75 placed on PM PM_3
[2025-12-19 10:21:20] [INFO] [STATE] VM vm_76 placed on PM PM_3
[2025-12-19 10:21:20] [INFO] [STATE] VM vm_77 placed on PM PM_3
[2025-12-19 10:21:20] [INFO] [STATE] VM vm_78 placed on PM PM_3
[2025-12-19 10:21:20] [INFO] [STATE] VM vm_79 placed on PM PM_3
[2025-12-19 10:21:20] [INFO] [STATE] VM vm_80 placed on PM PM_3
[2025-12-19 10:21:20] [INFO] [STATE] VM vm_81 placed on PM PM_3
[2025-12-19 10:21:20] [INFO] [STATE] VM vm_82 placed on PM PM_3
[2025-12-19 10:21:20] [INFO] [STATE] VM vm_83 placed on PM PM_3
[2025-12-19 10:21:20] [INFO] [STATE] VM vm_84 placed on PM PM_3
[2025-12-19 10:21:20] [INFO] [VM_EVENT] VM vm_85 created (pending) at t=100
[2025-12-19 10:21:20] [INFO] [VM_EVENT] VM vm_86 created (pending) at t=100
[2025-12-19 10:21:20] [INFO] [VM_EVENT] VM vm_87 created (pending) at t=100
[2025-12-19 10:21:20] [INFO] [VM_EVENT] VM vm_88 created (pending) at t=100
[2025-12-19 10:21:20] [INFO] [VM_EVENT] VM vm_89 created (pending) at t=100
[2025-12-19 10:21:20] [INFO] [VM_EVENT] VM vm_90 created (pending) at t=100
[2025-12-19 10:21:20] [INFO] [VM_EVENT] VM vm_91 created (pending) at t=100
[2025-12-19 10:21:20] [INFO] [VM_EVENT] VM vm_92 created (pending) at t=100
[2025-12-19 10:21:20] [INFO] [VM_EVENT] VM vm_93 created (pending) at t=100
[2025-12-19 10:21:20] [INFO] [VM_EVENT] VM vm_94 created (pending) at t=100
[2025-12-19 10:21:20] [INFO] [VM_EVENT] VM vm_95 created (pending) at t=100
[2025-12-19 10:21:20] [INFO] [VM_EVENT] VM vm_96 created (pending) at t=100
[2025-12-19 10:21:20] [INFO] [VM_EVENT] VM vm_97 created (pending) at t=100
[2025-12-19 10:21:20] [INFO] [VM_EVENT] VM vm_98 created (pending) at t=100
[2025-12-19 10:21:20] [INFO] [VM_EVENT] VM vm_99 created (pending) at t=100
[2025-12-19 10:21:20] [INFO] [VM_EVENT] VM vm_100 created (pending) at t=100
[2025-12-19 10:21:20] [INFO] [VM_EVENT] VM vm_101 created (pending) at t=100
[2025-12-19 10:21:20] [INFO] [VM_EVENT] VM vm_102 created (pending) at t=100
[2025-12-19 10:21:20] [INFO] [VM_EVENT] VM vm_103 created (pending) at t=100
[2025-12-19 10:21:20] [INFO] [VM_EVENT] VM vm_104 created (pending) at t=100
[2025-12-19 10:21:20] [INFO] [SCHEDULER] FCFS embed VM vm_85 -> PM PM_8 at t=100
[2025-12-19 10:21:20] [INFO] [SCHEDULER] FCFS embed VM vm_86 -> PM PM_8 at t=100
[2025-12-19 10:21:20] [INFO] [SCHEDULER] FCFS embed VM vm_87 -> PM PM_8 at t=100
[2025-12-19 10:21:20] [INFO] [SCHEDULER] FCFS embed VM vm_88 -> PM PM_8 at t=100
[2025-12-19 10:21:20] [INFO] [SCHEDULER] FCFS embed VM vm_89 -> PM PM_8 at t=100
[2025-12-19 10:21:20] [INFO] [SCHEDULER] FCFS embed VM vm_90 -> PM PM_8 at t=100
[2025-12-19 10:21:20] [INFO] [SCHEDULER] FCFS embed VM vm_91 -> PM PM_8 at t=100
[2025-12-19 10:21:20] [INFO] [SCHEDULER] FCFS embed VM vm_92 -> PM PM_8 at t=100
[2025-12-19 10:21:20] [INFO] [SCHEDULER] FCFS embed VM vm_93 -> PM PM_8 at t=100
[2025-12-19 10:21:20] [INFO] [SCHEDULER] FCFS embed VM vm_94 -> PM PM_8 at t=100
[2025-12-19 10:21:20] [INFO] [SCHEDULER] FCFS embed VM vm_95 -> PM PM_8 at t=100
[2025-12-19 10:21:20] [INFO] [SCHEDULER] FCFS embed VM vm_96 -> PM PM_8 at t=100
[2025-12-19 10:21:20] [INFO] [SCHEDULER] FCFS embed VM vm_97 -> PM PM_8 at t=100
[2025-12-19 10:21:20] [INFO] [SCHEDULER] FCFS embed VM vm_98 -> PM PM_8 at t=100
[2025-12-19 10:21:20] [INFO] [SCHEDULER] FCFS embed VM vm_99 -> PM PM_8 at t=100
[2025-12-19 10:21:20] [INFO] [SCHEDULER] FCFS embed VM vm_100 -> PM PM_8 at t=100
[2025-12-19 10:21:20] [INFO] [SCHEDULER] FCFS embed VM vm_101 -> PM PM_8 at t=100
[2025-12-19 10:21:20] [INFO] [SCHEDULER] FCFS embed VM vm_102 -> PM PM_8 at t=100
[2025-12-19 10:21:20] [INFO] [SCHEDULER] FCFS embed VM vm_103 -> PM PM_8 at t=100
[2025-12-19 10:21:20] [INFO] [SCHEDULER] FCFS embed VM vm_104 -> PM PM_8 at t=100
[2025-12-19 10:21:20] [INFO] [STATE] VM vm_85 placed on PM PM_8
[2025-12-19 10:21:20] [INFO] [STATE] VM vm_86 placed on PM PM_8
[2025-12-19 10:21:20] [INFO] [STATE] VM vm_87 placed on PM PM_8
[2025-12-19 10:21:20] [INFO] [STATE] VM vm_88 placed on PM PM_8
[2025-12-19 10:21:20] [INFO] [STATE] VM vm_89 placed on PM PM_8
[2025-12-19 10:21:20] [INFO] [STATE] VM vm_90 placed on PM PM_8
[2025-12-19 10:21:20] [INFO] [STATE] VM vm_91 placed on PM PM_8
[2025-12-19 10:21:20] [INFO] [STATE] VM vm_92 placed on PM PM_8
[2025-12-19 10:21:20] [INFO] [STATE] VM vm_93 placed on PM PM_8
[2025-12-19 10:21:20] [INFO] [STATE] VM vm_94 placed on PM PM_8
[2025-12-19 10:21:20] [INFO] [STATE] VM vm_95 placed on PM PM_8
[2025-12-19 10:21:20] [INFO] [STATE] VM vm_96 placed on PM PM_8
[2025-12-19 10:21:20] [INFO] [STATE] VM vm_97 placed on PM PM_8
[2025-12-19 10:21:20] [INFO] [STATE] VM vm_98 placed on PM PM_8
[2025-12-19 10:21:20] [INFO] [STATE] VM vm_99 placed on PM PM_8
[2025-12-19 10:21:20] [INFO] [STATE] VM vm_100 placed on PM PM_8
[2025-12-19 10:21:20] [INFO] [STATE] VM vm_101 placed on PM PM_8
[2025-12-19 10:21:20] [INFO] [STATE] VM vm_102 placed on PM PM_8
[2025-12-19 10:21:20] [INFO] [STATE] VM vm_103 placed on PM PM_8
[2025-12-19 10:21:20] [INFO] [STATE] VM vm_104 placed on PM PM_8
[2025-12-19 10:21:20] [INFO] [VM_EVENT] VM vm_105 created (pending) at t=101
[2025-12-19 10:21:20] [INFO] [VM_EVENT] VM vm_106 created (pending) at t=101
[2025-12-19 10:21:20] [INFO] [VM_EVENT] VM vm_107 created (pending) at t=101
[2025-12-19 10:21:20] [INFO] [VM_EVENT] VM vm_108 created (pending) at t=101
[2025-12-19 10:21:20] [INFO] [VM_EVENT] VM vm_109 created (pending) at t=101
[2025-12-19 10:21:20] [INFO] [VM_EVENT] VM vm_110 created (pending) at t=101
[2025-12-19 10:21:20] [INFO] [VM_EVENT] VM vm_111 created (pending) at t=101
[2025-12-19 10:21:20] [INFO] [VM_EVENT] VM vm_112 created (pending) at t=101
[2025-12-19 10:21:20] [INFO] [VM_EVENT] VM vm_113 created (pending) at t=101
[2025-12-19 10:21:20] [INFO] [VM_EVENT] VM vm_114 created (pending) at t=101
[2025-12-19 10:21:20] [INFO] [VM_EVENT] VM vm_115 created (pending) at t=101
[2025-12-19 10:21:20] [INFO] [VM_EVENT] VM vm_116 created (pending) at t=101
[2025-12-19 10:21:20] [INFO] [VM_EVENT] VM vm_117 created (pending) at t=101
[2025-12-19 10:21:20] [INFO] [VM_EVENT] VM vm_118 created (pending) at t=101
[2025-12-19 10:21:20] [INFO] [VM_EVENT] VM vm_119 created (pending) at t=101
[2025-12-19 10:21:20] [INFO] [VM_EVENT] VM vm_120 created (pending) at t=101
[2025-12-19 10:21:20] [INFO] [VM_EVENT] VM vm_121 created (pending) at t=101
[2025-12-19 10:21:20] [INFO] [VM_EVENT] VM vm_122 created (pending) at t=101
[2025-12-19 10:21:20] [INFO] [SCHEDULER] FCFS embed VM vm_105 -> PM PM_0 at t=101
[2025-12-19 10:21:20] [INFO] [SCHEDULER] FCFS embed VM vm_106 -> PM PM_0 at t=101
[2025-12-19 10:21:20] [INFO] [SCHEDULER] FCFS embed VM vm_107 -> PM PM_0 at t=101
[2025-12-19 10:21:20] [INFO] [SCHEDULER] FCFS embed VM vm_108 -> PM PM_0 at t=101
[2025-12-19 10:21:20] [INFO] [SCHEDULER] FCFS embed VM vm_109 -> PM PM_0 at t=101
[2025-12-19 10:21:20] [INFO] [SCHEDULER] FCFS embed VM vm_110 -> PM PM_0 at t=101
[2025-12-19 10:21:20] [INFO] [SCHEDULER] FCFS embed VM vm_111 -> PM PM_0 at t=101
[2025-12-19 10:21:20] [INFO] [SCHEDULER] FCFS embed VM vm_112 -> PM PM_0 at t=101
[2025-12-19 10:21:20] [INFO] [SCHEDULER] FCFS embed VM vm_113 -> PM PM_0 at t=101
[2025-12-19 10:21:20] [INFO] [SCHEDULER] FCFS embed VM vm_114 -> PM PM_0 at t=101
[2025-12-19 10:21:20] [INFO] [SCHEDULER] FCFS embed VM vm_115 -> PM PM_0 at t=101
[2025-12-19 10:21:20] [INFO] [SCHEDULER] FCFS embed VM vm_116 -> PM PM_0 at t=101
[2025-12-19 10:21:20] [INFO] [SCHEDULER] FCFS embed VM vm_117 -> PM PM_0 at t=101
[2025-12-19 10:21:20] [INFO] [SCHEDULER] FCFS embed VM vm_118 -> PM PM_0 at t=101
[2025-12-19 10:21:20] [INFO] [SCHEDULER] FCFS embed VM vm_119 -> PM PM_0 at t=101
[2025-12-19 10:21:20] [INFO] [SCHEDULER] FCFS embed VM vm_120 -> PM PM_0 at t=101
[2025-12-19 10:21:20] [INFO] [SCHEDULER] FCFS embed VM vm_121 -> PM PM_0 at t=101
[2025-12-19 10:21:20] [INFO] [SCHEDULER] FCFS embed VM vm_122 -> PM PM_0 at t=101
[2025-12-19 10:21:20] [INFO] [STATE] VM vm_105 placed on PM PM_0
[2025-12-19 10:21:20] [INFO] [STATE] VM vm_106 placed on PM PM_0
[2025-12-19 10:21:20] [INFO] [STATE] VM vm_107 placed on PM PM_0
[2025-12-19 10:21:20] [INFO] [STATE] VM vm_108 placed on PM PM_0
[2025-12-19 10:21:20] [INFO] [STATE] VM vm_109 placed on PM PM_0
[2025-12-19 10:21:20] [INFO] [STATE] VM vm_110 placed on PM PM_0
[2025-12-19 10:21:20] [INFO] [STATE] VM vm_111 placed on PM PM_0
[2025-12-19 10:21:20] [INFO] [STATE] VM vm_112 placed on PM PM_0
[2025-12-19 10:21:20] [INFO] [STATE] VM vm_113 placed on PM PM_0
[2025-12-19 10:21:20] [INFO] [STATE] VM vm_114 placed on PM PM_0
[2025-12-19 10:21:20] [INFO] [STATE] VM vm_115 placed on PM PM_0
[2025-12-19 10:21:20] [INFO] [STATE] VM vm_116 placed on PM PM_0
[2025-12-19 10:21:20] [INFO] [STATE] VM vm_117 placed on PM PM_0
[2025-12-19 10:21:20] [INFO] [STATE] VM vm_118 placed on PM PM_0
[2025-12-19 10:21:20] [INFO] [STATE] VM vm_119 placed on PM PM_0
[2025-12-19 10:21:20] [INFO] [STATE] VM vm_120 placed on PM PM_0
[2025-12-19 10:21:20] [INFO] [STATE] VM vm_121 placed on PM PM_0
[2025-12-19 10:21:20] [INFO] [STATE] VM vm_122 placed on PM PM_0
[2025-12-19 10:21:20] [INFO] [VM_EVENT] VM vm_123 created (pending) at t=102
[2025-12-19 10:21:20] [INFO] [VM_EVENT] VM vm_124 created (pending) at t=102
[2025-12-19 10:21:20] [INFO] [VM_EVENT] VM vm_125 created (pending) at t=102
[2025-12-19 10:21:20] [INFO] [VM_EVENT] VM vm_126 created (pending) at t=102
[2025-12-19 10:21:20] [INFO] [VM_EVENT] VM vm_127 created (pending) at t=102
[2025-12-19 10:21:20] [INFO] [VM_EVENT] VM vm_128 created (pending) at t=102
[2025-12-19 10:21:20] [INFO] [VM_EVENT] VM vm_129 created (pending) at t=102
[2025-12-19 10:21:20] [INFO] [VM_EVENT] VM vm_130 created (pending) at t=102
[2025-12-19 10:21:20] [INFO] [VM_EVENT] VM vm_131 created (pending) at t=102
[2025-12-19 10:21:20] [INFO] [VM_EVENT] VM vm_132 created (pending) at t=102
[2025-12-19 10:21:20] [INFO] [VM_EVENT] VM vm_133 created (pending) at t=102
[2025-12-19 10:21:20] [INFO] [VM_EVENT] VM vm_134 created (pending) at t=102
[2025-12-19 10:21:20] [INFO] [VM_EVENT] VM vm_135 created (pending) at t=102
[2025-12-19 10:21:20] [INFO] [VM_EVENT] VM vm_136 created (pending) at t=102
[2025-12-19 10:21:20] [INFO] [VM_EVENT] VM vm_137 created (pending) at t=102
[2025-12-19 10:21:20] [INFO] [VM_EVENT] VM vm_138 created (pending) at t=102
[2025-12-19 10:21:20] [INFO] [VM_EVENT] VM vm_139 created (pending) at t=102
[2025-12-19 10:21:20] [INFO] [VM_EVENT] VM vm_140 created (pending) at t=102
[2025-12-19 10:21:20] [INFO] [VM_EVENT] VM vm_141 created (pending) at t=102
[2025-12-19 10:21:20] [INFO] [VM_EVENT] VM vm_142 created (pending) at t=102
[2025-12-19 10:21:20] [INFO] [VM_EVENT] VM vm_143 created (pending) at t=102
[2025-12-19 10:21:20] [INFO] [VM_EVENT] VM vm_144 created (pending) at t=102
[2025-12-19 10:21:20] [INFO] [VM_EVENT] VM vm_145 created (pending) at t=102
[2025-12-19 10:21:20] [INFO] [VM_EVENT] VM vm_146 created (pending) at t=102
[2025-12-19 10:21:20] [INFO] [VM_EVENT] VM vm_147 created (pending) at t=102
[2025-12-19 10:21:20] [INFO] [VM_EVENT] VM vm_148 created (pending) at t=102
[2025-12-19 10:21:20] [INFO] [VM_EVENT] VM vm_149 created (pending) at t=102
[2025-12-19 10:21:20] [INFO] [VM_EVENT] VM vm_150 created (pending) at t=102
[2025-12-19 10:21:20] [INFO] [VM_EVENT] VM vm_151 created (pending) at t=102
[2025-12-19 10:21:20] [INFO] [SCHEDULER] FCFS embed VM vm_123 -> PM PM_4 at t=102
[2025-12-19 10:21:20] [INFO] [SCHEDULER] FCFS embed VM vm_124 -> PM PM_4 at t=102
[2025-12-19 10:21:20] [INFO] [SCHEDULER] FCFS embed VM vm_125 -> PM PM_4 at t=102
[2025-12-19 10:21:20] [INFO] [SCHEDULER] FCFS embed VM vm_126 -> PM PM_4 at t=102
[2025-12-19 10:21:20] [INFO] [SCHEDULER] FCFS embed VM vm_127 -> PM PM_4 at t=102
[2025-12-19 10:21:20] [INFO] [SCHEDULER] FCFS embed VM vm_128 -> PM PM_4 at t=102
[2025-12-19 10:21:20] [INFO] [SCHEDULER] FCFS embed VM vm_129 -> PM PM_4 at t=102
[2025-12-19 10:21:20] [INFO] [SCHEDULER] FCFS embed VM vm_130 -> PM PM_4 at t=102
[2025-12-19 10:21:20] [INFO] [SCHEDULER] FCFS embed VM vm_131 -> PM PM_4 at t=102
[2025-12-19 10:21:20] [INFO] [SCHEDULER] FCFS embed VM vm_132 -> PM PM_4 at t=102
[2025-12-19 10:21:20] [INFO] [SCHEDULER] FCFS embed VM vm_133 -> PM PM_4 at t=102
[2025-12-19 10:21:20] [INFO] [SCHEDULER] FCFS embed VM vm_134 -> PM PM_4 at t=102
[2025-12-19 10:21:20] [INFO] [SCHEDULER] FCFS embed VM vm_135 -> PM PM_4 at t=102
[2025-12-19 10:21:20] [INFO] [SCHEDULER] FCFS embed VM vm_136 -> PM PM_4 at t=102
[2025-12-19 10:21:20] [INFO] [SCHEDULER] FCFS embed VM vm_137 -> PM PM_4 at t=102
[2025-12-19 10:21:20] [INFO] [SCHEDULER] FCFS embed VM vm_138 -> PM PM_4 at t=102
[2025-12-19 10:21:20] [INFO] [SCHEDULER] FCFS embed VM vm_139 -> PM PM_4 at t=102
[2025-12-19 10:21:20] [INFO] [SCHEDULER] FCFS embed VM vm_140 -> PM PM_4 at t=102
[2025-12-19 10:21:20] [INFO] [SCHEDULER] FCFS embed VM vm_141 -> PM PM_4 at t=102
[2025-12-19 10:21:20] [INFO] [SCHEDULER] FCFS embed VM vm_142 -> PM PM_4 at t=102
[2025-12-19 10:21:20] [INFO] [SCHEDULER] FCFS embed VM vm_143 -> PM PM_4 at t=102
[2025-12-19 10:21:20] [INFO] [SCHEDULER] FCFS embed VM vm_144 -> PM PM_4 at t=102
[2025-12-19 10:21:20] [INFO] [SCHEDULER] FCFS embed VM vm_145 -> PM PM_4 at t=102
[2025-12-19 10:21:20] [INFO] [SCHEDULER] FCFS embed VM vm_146 -> PM PM_4 at t=102
[2025-12-19 10:21:20] [INFO] [SCHEDULER] FCFS embed VM vm_147 -> PM PM_4 at t=102
[2025-12-19 10:21:20] [INFO] [SCHEDULER] FCFS embed VM vm_148 -> PM PM_4 at t=102
[2025-12-19 10:21:20] [INFO] [SCHEDULER] FCFS embed VM vm_149 -> PM PM_4 at t=102
[2025-12-19 10:21:20] [INFO] [SCHEDULER] FCFS embed VM vm_150 -> PM PM_4 at t=102
[2025-12-19 10:21:20] [INFO] [SCHEDULER] FCFS embed VM vm_151 -> PM PM_4 at t=102
[2025-12-19 10:21:20] [INFO] [STATE] VM vm_123 placed on PM PM_4
[2025-12-19 10:21:20] [INFO] [STATE] VM vm_124 placed on PM PM_4
[2025-12-19 10:21:20] [INFO] [STATE] VM vm_125 placed on PM PM_4
[2025-12-19 10:21:20] [INFO] [STATE] VM vm_126 placed on PM PM_4
[2025-12-19 10:21:20] [INFO] [STATE] VM vm_127 placed on PM PM_4
[2025-12-19 10:21:20] [INFO] [STATE] VM vm_128 placed on PM PM_4
[2025-12-19 10:21:20] [INFO] [STATE] VM vm_129 placed on PM PM_4
[2025-12-19 10:21:20] [INFO] [STATE] VM vm_130 placed on PM PM_4
[2025-12-19 10:21:20] [INFO] [STATE] VM vm_131 placed on PM PM_4
[2025-12-19 10:21:20] [INFO] [STATE] VM vm_132 placed on PM PM_4
[2025-12-19 10:21:20] [INFO] [STATE] VM vm_133 placed on PM PM_4
[2025-12-19 10:21:20] [INFO] [STATE] VM vm_134 placed on PM PM_4
[2025-12-19 10:21:20] [INFO] [STATE] VM vm_135 placed on PM PM_4
[2025-12-19 10:21:20] [INFO] [STATE] VM vm_136 placed on PM PM_4
[2025-12-19 10:21:20] [INFO] [STATE] VM vm_137 placed on PM PM_4
[2025-12-19 10:21:20] [INFO] [STATE] VM vm_138 placed on PM PM_4
[2025-12-19 10:21:20] [INFO] [STATE] VM vm_139 placed on PM PM_4
[2025-12-19 10:21:20] [INFO] [STATE] VM vm_140 placed on PM PM_4
[2025-12-19 10:21:20] [INFO] [STATE] VM vm_141 placed on PM PM_4
[2025-12-19 10:21:20] [INFO] [STATE] VM vm_142 placed on PM PM_4
[2025-12-19 10:21:20] [INFO] [STATE] VM vm_143 placed on PM PM_4
[2025-12-19 10:21:20] [INFO] [STATE] VM vm_144 placed on PM PM_4
[2025-12-19 10:21:20] [INFO] [STATE] VM vm_145 placed on PM PM_4
[2025-12-19 10:21:20] [INFO] [STATE] VM vm_146 placed on PM PM_4
[2025-12-19 10:21:20] [INFO] [STATE] VM vm_147 placed on PM PM_4
[2025-12-19 10:21:20] [INFO] [STATE] VM vm_148 placed on PM PM_4
[2025-12-19 10:21:20] [INFO] [STATE] VM vm_149 placed on PM PM_4
[2025-12-19 10:21:20] [INFO] [STATE] VM vm_150 placed on PM PM_4
[2025-12-19 10:21:20] [INFO] [STATE] VM vm_151 placed on PM PM_4
[2025-12-19 10:21:20] [INFO] [VM_EVENT] VM vm_152 created (pending) at t=103
[2025-12-19 10:21:20] [INFO] [VM_EVENT] VM vm_153 created (pending) at t=103
[2025-12-19 10:21:20] [INFO] [VM_EVENT] VM vm_154 created (pending) at t=103
[2025-12-19 10:21:20] [INFO] [VM_EVENT] VM vm_155 created (pending) at t=103
[2025-12-19 10:21:20] [INFO] [VM_EVENT] VM vm_156 created (pending) at t=103
[2025-12-19 10:21:20] [INFO] [VM_EVENT] VM vm_157 created (pending) at t=103
[2025-12-19 10:21:20] [INFO] [VM_EVENT] VM vm_158 created (pending) at t=103
[2025-12-19 10:21:20] [INFO] [VM_EVENT] VM vm_159 created (pending) at t=103
[2025-12-19 10:21:20] [INFO] [VM_EVENT] VM vm_160 created (pending) at t=103
[2025-12-19 10:21:20] [INFO] [VM_EVENT] VM vm_161 created (pending) at t=103
[2025-12-19 10:21:20] [INFO] [VM_EVENT] VM vm_162 created (pending) at t=103
[2025-12-19 10:21:20] [INFO] [VM_EVENT] VM vm_163 created (pending) at t=103
[2025-12-19 10:21:20] [INFO] [VM_EVENT] VM vm_164 created (pending) at t=103
[2025-12-19 10:21:20] [INFO] [VM_EVENT] VM vm_165 created (pending) at t=103
[2025-12-19 10:21:20] [INFO] [VM_EVENT] VM vm_166 created (pending) at t=103
[2025-12-19 10:21:20] [INFO] [VM_EVENT] VM vm_167 created (pending) at t=103
[2025-12-19 10:21:20] [INFO] [VM_EVENT] VM vm_168 created (pending) at t=103
[2025-12-19 10:21:20] [INFO] [VM_EVENT] VM vm_169 created (pending) at t=103
[2025-12-19 10:21:20] [INFO] [VM_EVENT] VM vm_170 created (pending) at t=103
[2025-12-19 10:21:20] [INFO] [VM_EVENT] VM vm_171 created (pending) at t=103
[2025-12-19 10:21:20] [INFO] [VM_EVENT] VM vm_172 created (pending) at t=103
[2025-12-19 10:21:20] [INFO] [VM_EVENT] VM vm_173 created (pending) at t=103
[2025-12-19 10:21:20] [INFO] [VM_EVENT] VM vm_174 created (pending) at t=103
[2025-12-19 10:21:20] [INFO] [SCHEDULER] FCFS embed VM vm_152 -> PM PM_3 at t=103
[2025-12-19 10:21:20] [INFO] [SCHEDULER] FCFS embed VM vm_153 -> PM PM_3 at t=103
[2025-12-19 10:21:20] [INFO] [SCHEDULER] FCFS embed VM vm_154 -> PM PM_3 at t=103
[2025-12-19 10:21:20] [INFO] [SCHEDULER] FCFS embed VM vm_155 -> PM PM_3 at t=103
[2025-12-19 10:21:20] [INFO] [SCHEDULER] FCFS embed VM vm_156 -> PM PM_3 at t=103
[2025-12-19 10:21:20] [INFO] [SCHEDULER] FCFS embed VM vm_157 -> PM PM_3 at t=103
[2025-12-19 10:21:20] [INFO] [SCHEDULER] FCFS embed VM vm_158 -> PM PM_3 at t=103
[2025-12-19 10:21:20] [INFO] [SCHEDULER] FCFS embed VM vm_159 -> PM PM_3 at t=103
[2025-12-19 10:21:20] [INFO] [SCHEDULER] FCFS embed VM vm_160 -> PM PM_3 at t=103
[2025-12-19 10:21:20] [INFO] [SCHEDULER] FCFS embed VM vm_161 -> PM PM_3 at t=103
[2025-12-19 10:21:20] [INFO] [SCHEDULER] FCFS embed VM vm_162 -> PM PM_3 at t=103
[2025-12-19 10:21:20] [INFO] [SCHEDULER] FCFS embed VM vm_163 -> PM PM_3 at t=103
[2025-12-19 10:21:20] [INFO] [SCHEDULER] FCFS embed VM vm_164 -> PM PM_3 at t=103
[2025-12-19 10:21:20] [INFO] [SCHEDULER] FCFS embed VM vm_165 -> PM PM_3 at t=103
[2025-12-19 10:21:20] [INFO] [SCHEDULER] FCFS embed VM vm_166 -> PM PM_3 at t=103
[2025-12-19 10:21:20] [INFO] [SCHEDULER] FCFS embed VM vm_167 -> PM PM_3 at t=103
[2025-12-19 10:21:20] [INFO] [SCHEDULER] FCFS embed VM vm_168 -> PM PM_3 at t=103
[2025-12-19 10:21:20] [INFO] [SCHEDULER] FCFS embed VM vm_169 -> PM PM_3 at t=103
[2025-12-19 10:21:20] [INFO] [SCHEDULER] FCFS embed VM vm_170 -> PM PM_3 at t=103
[2025-12-19 10:21:20] [INFO] [SCHEDULER] FCFS embed VM vm_171 -> PM PM_3 at t=103
[2025-12-19 10:21:20] [INFO] [SCHEDULER] FCFS embed VM vm_172 -> PM PM_3 at t=103
[2025-12-19 10:21:20] [INFO] [SCHEDULER] FCFS embed VM vm_173 -> PM PM_3 at t=103
[2025-12-19 10:21:20] [INFO] [SCHEDULER] FCFS embed VM vm_174 -> PM PM_3 at t=103
[2025-12-19 10:21:20] [INFO] [STATE] VM vm_152 placed on PM PM_3
[2025-12-19 10:21:20] [INFO] [STATE] VM vm_153 placed on PM PM_3
[2025-12-19 10:21:20] [INFO] [STATE] VM vm_154 placed on PM PM_3
[2025-12-19 10:21:20] [INFO] [STATE] VM vm_155 placed on PM PM_3
[2025-12-19 10:21:20] [INFO] [STATE] VM vm_156 placed on PM PM_3
[2025-12-19 10:21:20] [INFO] [STATE] VM vm_157 placed on PM PM_3
[2025-12-19 10:21:20] [INFO] [STATE] VM vm_158 placed on PM PM_3
[2025-12-19 10:21:20] [INFO] [STATE] VM vm_159 placed on PM PM_3
[2025-12-19 10:21:20] [INFO] [STATE] VM vm_160 placed on PM PM_3
[2025-12-19 10:21:20] [INFO] [STATE] VM vm_161 placed on PM PM_3
[2025-12-19 10:21:20] [INFO] [STATE] VM vm_162 placed on PM PM_3
[2025-12-19 10:21:20] [INFO] [STATE] VM vm_163 placed on PM PM_3
[2025-12-19 10:21:20] [INFO] [STATE] VM vm_164 placed on PM PM_3
[2025-12-19 10:21:20] [INFO] [STATE] VM vm_165 placed on PM PM_3
[2025-12-19 10:21:20] [INFO] [STATE] VM vm_166 placed on PM PM_3
[2025-12-19 10:21:20] [INFO] [STATE] VM vm_167 placed on PM PM_3
[2025-12-19 10:21:20] [INFO] [STATE] VM vm_168 placed on PM PM_3
[2025-12-19 10:21:20] [INFO] [STATE] VM vm_169 placed on PM PM_3
[2025-12-19 10:21:20] [INFO] [STATE] VM vm_170 placed on PM PM_3
[2025-12-19 10:21:20] [INFO] [STATE] VM vm_171 placed on PM PM_3
[2025-12-19 10:21:20] [INFO] [STATE] VM vm_172 placed on PM PM_3
[2025-12-19 10:21:20] [INFO] [STATE] VM vm_173 placed on PM PM_3
[2025-12-19 10:21:20] [INFO] [STATE] VM vm_174 placed on PM PM_3
[2025-12-19 10:21:20] [INFO] [VM_EVENT] VM vm_175 created (pending) at t=104
[2025-12-19 10:21:20] [INFO] [VM_EVENT] VM vm_176 created (pending) at t=104
[2025-12-19 10:21:20] [INFO] [VM_EVENT] VM vm_177 created (pending) at t=104
[2025-12-19 10:21:20] [INFO] [VM_EVENT] VM vm_178 created (pending) at t=104
[2025-12-19 10:21:20] [INFO] [VM_EVENT] VM vm_179 created (pending) at t=104
[2025-12-19 10:21:20] [INFO] [VM_EVENT] VM vm_180 created (pending) at t=104
[2025-12-19 10:21:20] [INFO] [VM_EVENT] VM vm_181 created (pending) at t=104
[2025-12-19 10:21:20] [INFO] [VM_EVENT] VM vm_182 created (pending) at t=104
[2025-12-19 10:21:20] [INFO] [VM_EVENT] VM vm_183 created (pending) at t=104
[2025-12-19 10:21:20] [INFO] [VM_EVENT] VM vm_184 created (pending) at t=104
[2025-12-19 10:21:20] [INFO] [VM_EVENT] VM vm_185 created (pending) at t=104
[2025-12-19 10:21:20] [INFO] [VM_EVENT] VM vm_186 created (pending) at t=104
[2025-12-19 10:21:20] [INFO] [VM_EVENT] VM vm_187 created (pending) at t=104
[2025-12-19 10:21:20] [INFO] [VM_EVENT] VM vm_188 created (pending) at t=104
[2025-12-19 10:21:20] [INFO] [VM_EVENT] VM vm_189 created (pending) at t=104
[2025-12-19 10:21:20] [INFO] [VM_EVENT] VM vm_190 created (pending) at t=104
[2025-12-19 10:21:20] [INFO] [SCHEDULER] FCFS embed VM vm_175 -> PM PM_4 at t=104
[2025-12-19 10:21:20] [INFO] [SCHEDULER] FCFS embed VM vm_176 -> PM PM_4 at t=104
[2025-12-19 10:21:20] [INFO] [SCHEDULER] FCFS embed VM vm_177 -> PM PM_4 at t=104
[2025-12-19 10:21:20] [INFO] [SCHEDULER] FCFS embed VM vm_178 -> PM PM_4 at t=104
[2025-12-19 10:21:20] [INFO] [SCHEDULER] FCFS embed VM vm_179 -> PM PM_4 at t=104
[2025-12-19 10:21:20] [INFO] [SCHEDULER] FCFS embed VM vm_180 -> PM PM_4 at t=104
[2025-12-19 10:21:20] [INFO] [SCHEDULER] FCFS embed VM vm_181 -> PM PM_4 at t=104
[2025-12-19 10:21:20] [INFO] [SCHEDULER] FCFS embed VM vm_182 -> PM PM_4 at t=104
[2025-12-19 10:21:20] [INFO] [SCHEDULER] FCFS embed VM vm_183 -> PM PM_4 at t=104
[2025-12-19 10:21:20] [INFO] [SCHEDULER] FCFS embed VM vm_184 -> PM PM_4 at t=104
[2025-12-19 10:21:20] [INFO] [SCHEDULER] FCFS embed VM vm_185 -> PM PM_4 at t=104
[2025-12-19 10:21:20] [INFO] [SCHEDULER] FCFS embed VM vm_186 -> PM PM_4 at t=104
[2025-12-19 10:21:20] [INFO] [SCHEDULER] FCFS embed VM vm_187 -> PM PM_4 at t=104
[2025-12-19 10:21:20] [INFO] [SCHEDULER] FCFS embed VM vm_188 -> PM PM_4 at t=104
[2025-12-19 10:21:20] [INFO] [SCHEDULER] FCFS embed VM vm_189 -> PM PM_4 at t=104
[2025-12-19 10:21:20] [INFO] [SCHEDULER] FCFS embed VM vm_190 -> PM PM_4 at t=104
[2025-12-19 10:21:20] [INFO] [STATE] VM vm_175 placed on PM PM_4
[2025-12-19 10:21:20] [INFO] [STATE] VM vm_176 placed on PM PM_4
[2025-12-19 10:21:20] [INFO] [STATE] VM vm_177 placed on PM PM_4
[2025-12-19 10:21:20] [INFO] [STATE] VM vm_178 placed on PM PM_4
[2025-12-19 10:21:20] [INFO] [STATE] VM vm_179 placed on PM PM_4
[2025-12-19 10:21:20] [INFO] [STATE] VM vm_180 placed on PM PM_4
[2025-12-19 10:21:20] [INFO] [STATE] VM vm_181 placed on PM PM_4
[2025-12-19 10:21:20] [INFO] [STATE] VM vm_182 placed on PM PM_4
[2025-12-19 10:21:20] [INFO] [STATE] VM vm_183 placed on PM PM_4
[2025-12-19 10:21:20] [INFO] [STATE] VM vm_184 placed on PM PM_4
[2025-12-19 10:21:20] [INFO] [STATE] VM vm_185 placed on PM PM_4
[2025-12-19 10:21:20] [INFO] [STATE] VM vm_186 placed on PM PM_4
[2025-12-19 10:21:20] [INFO] [STATE] VM vm_187 placed on PM PM_4
[2025-12-19 10:21:20] [INFO] [STATE] VM vm_188 placed on PM PM_4
[2025-12-19 10:21:20] [INFO] [STATE] VM vm_189 placed on PM PM_4
[2025-12-19 10:21:20] [INFO] [STATE] VM vm_190 placed on PM PM_4
[2025-12-19 10:21:20] [INFO] [VM_EVENT] VM vm_191 created (pending) at t=105
[2025-12-19 10:21:20] [INFO] [VM_EVENT] VM vm_192 created (pending) at t=105
[2025-12-19 10:21:20] [INFO] [VM_EVENT] VM vm_193 created (pending) at t=105
[2025-12-19 10:21:20] [INFO] [VM_EVENT] VM vm_194 created (pending) at t=105
[2025-12-19 10:21:20] [INFO] [VM_EVENT] VM vm_195 created (pending) at t=105
[2025-12-19 10:21:20] [INFO] [VM_EVENT] VM vm_196 created (pending) at t=105
[2025-12-19 10:21:20] [INFO] [VM_EVENT] VM vm_197 created (pending) at t=105
[2025-12-19 10:21:20] [INFO] [VM_EVENT] VM vm_198 created (pending) at t=105
[2025-12-19 10:21:20] [INFO] [VM_EVENT] VM vm_199 created (pending) at t=105
[2025-12-19 10:21:20] [INFO] [VM_EVENT] VM vm_200 created (pending) at t=105
[2025-12-19 10:21:20] [INFO] [VM_EVENT] VM vm_201 created (pending) at t=105
[2025-12-19 10:21:20] [INFO] [VM_EVENT] VM vm_202 created (pending) at t=105
[2025-12-19 10:21:20] [INFO] [VM_EVENT] VM vm_203 created (pending) at t=105
[2025-12-19 10:21:20] [INFO] [SCHEDULER] FCFS embed VM vm_191 -> PM PM_5 at t=105
[2025-12-19 10:21:20] [INFO] [SCHEDULER] FCFS embed VM vm_192 -> PM PM_5 at t=105
[2025-12-19 10:21:20] [INFO] [SCHEDULER] FCFS embed VM vm_193 -> PM PM_5 at t=105
[2025-12-19 10:21:20] [INFO] [SCHEDULER] FCFS embed VM vm_194 -> PM PM_5 at t=105
[2025-12-19 10:21:20] [INFO] [SCHEDULER] FCFS embed VM vm_195 -> PM PM_5 at t=105
[2025-12-19 10:21:20] [INFO] [SCHEDULER] FCFS embed VM vm_196 -> PM PM_5 at t=105
[2025-12-19 10:21:20] [INFO] [SCHEDULER] FCFS embed VM vm_197 -> PM PM_5 at t=105
[2025-12-19 10:21:20] [INFO] [SCHEDULER] FCFS embed VM vm_198 -> PM PM_5 at t=105
[2025-12-19 10:21:20] [INFO] [SCHEDULER] FCFS embed VM vm_199 -> PM PM_5 at t=105
[2025-12-19 10:21:20] [INFO] [SCHEDULER] FCFS embed VM vm_200 -> PM PM_5 at t=105
[2025-12-19 10:21:20] [INFO] [SCHEDULER] FCFS embed VM vm_201 -> PM PM_5 at t=105
[2025-12-19 10:21:20] [INFO] [SCHEDULER] FCFS embed VM vm_202 -> PM PM_5 at t=105
[2025-12-19 10:21:20] [INFO] [SCHEDULER] FCFS embed VM vm_203 -> PM PM_5 at t=105
[2025-12-19 10:21:20] [INFO] [STATE] VM vm_191 placed on PM PM_5
[2025-12-19 10:21:20] [INFO] [STATE] VM vm_192 placed on PM PM_5
[2025-12-19 10:21:20] [INFO] [STATE] VM vm_193 placed on PM PM_5
[2025-12-19 10:21:20] [INFO] [STATE] VM vm_194 placed on PM PM_5
[2025-12-19 10:21:20] [INFO] [STATE] VM vm_195 placed on PM PM_5
[2025-12-19 10:21:20] [INFO] [STATE] VM vm_196 placed on PM PM_5
[2025-12-19 10:21:20] [INFO] [STATE] VM vm_197 placed on PM PM_5
[2025-12-19 10:21:20] [INFO] [STATE] VM vm_198 placed on PM PM_5
[2025-12-19 10:21:20] [INFO] [STATE] VM vm_199 placed on PM PM_5
[2025-12-19 10:21:20] [INFO] [STATE] VM vm_200 placed on PM PM_5
[2025-12-19 10:21:20] [INFO] [STATE] VM vm_201 placed on PM PM_5
[2025-12-19 10:21:20] [INFO] [STATE] VM vm_202 placed on PM PM_5
[2025-12-19 10:21:20] [INFO] [STATE] VM vm_203 placed on PM PM_5
[2025-12-19 10:21:20] [INFO] [VM_EVENT] VM vm_204 created (pending) at t=106
[2025-12-19 10:21:20] [INFO] [VM_EVENT] VM vm_205 created (pending) at t=106
[2025-12-19 10:21:20] [INFO] [VM_EVENT] VM vm_206 created (pending) at t=106
[2025-12-19 10:21:20] [INFO] [VM_EVENT] VM vm_207 created (pending) at t=106
[2025-12-19 10:21:20] [INFO] [VM_EVENT] VM vm_208 created (pending) at t=106
[2025-12-19 10:21:20] [INFO] [VM_EVENT] VM vm_209 created (pending) at t=106
[2025-12-19 10:21:20] [INFO] [VM_EVENT] VM vm_210 created (pending) at t=106
[2025-12-19 10:21:20] [INFO] [VM_EVENT] VM vm_211 created (pending) at t=106
[2025-12-19 10:21:20] [INFO] [VM_EVENT] VM vm_212 created (pending) at t=106
[2025-12-19 10:21:20] [INFO] [VM_EVENT] VM vm_213 created (pending) at t=106
[2025-12-19 10:21:20] [INFO] [VM_EVENT] VM vm_214 created (pending) at t=106
[2025-12-19 10:21:20] [INFO] [VM_EVENT] VM vm_215 created (pending) at t=106
[2025-12-19 10:21:20] [INFO] [VM_EVENT] VM vm_216 created (pending) at t=106
[2025-12-19 10:21:20] [INFO] [VM_EVENT] VM vm_217 created (pending) at t=106
[2025-12-19 10:21:20] [INFO] [VM_EVENT] VM vm_218 created (pending) at t=106
[2025-12-19 10:21:20] [INFO] [VM_EVENT] VM vm_219 created (pending) at t=106
[2025-12-19 10:21:20] [INFO] [VM_EVENT] VM vm_220 created (pending) at t=106
[2025-12-19 10:21:20] [INFO] [VM_EVENT] VM vm_221 created (pending) at t=106
[2025-12-19 10:21:20] [INFO] [VM_EVENT] VM vm_222 created (pending) at t=106
[2025-12-19 10:21:20] [INFO] [SCHEDULER] FCFS embed VM vm_204 -> PM PM_7 at t=106
[2025-12-19 10:21:20] [INFO] [SCHEDULER] FCFS embed VM vm_205 -> PM PM_7 at t=106
[2025-12-19 10:21:20] [INFO] [SCHEDULER] FCFS embed VM vm_206 -> PM PM_7 at t=106
[2025-12-19 10:21:20] [INFO] [SCHEDULER] FCFS embed VM vm_207 -> PM PM_7 at t=106
[2025-12-19 10:21:20] [INFO] [SCHEDULER] FCFS embed VM vm_208 -> PM PM_7 at t=106
[2025-12-19 10:21:20] [INFO] [SCHEDULER] FCFS embed VM vm_209 -> PM PM_7 at t=106
[2025-12-19 10:21:20] [INFO] [SCHEDULER] FCFS embed VM vm_210 -> PM PM_7 at t=106
[2025-12-19 10:21:20] [INFO] [SCHEDULER] FCFS embed VM vm_211 -> PM PM_7 at t=106
[2025-12-19 10:21:20] [INFO] [SCHEDULER] FCFS embed VM vm_212 -> PM PM_7 at t=106
[2025-12-19 10:21:20] [INFO] [SCHEDULER] FCFS embed VM vm_213 -> PM PM_7 at t=106
[2025-12-19 10:21:20] [INFO] [SCHEDULER] FCFS embed VM vm_214 -> PM PM_7 at t=106
[2025-12-19 10:21:20] [INFO] [SCHEDULER] FCFS embed VM vm_215 -> PM PM_7 at t=106
[2025-12-19 10:21:20] [INFO] [SCHEDULER] FCFS embed VM vm_216 -> PM PM_7 at t=106
[2025-12-19 10:21:20] [INFO] [SCHEDULER] FCFS embed VM vm_217 -> PM PM_7 at t=106
[2025-12-19 10:21:20] [INFO] [SCHEDULER] FCFS embed VM vm_218 -> PM PM_7 at t=106
[2025-12-19 10:21:20] [INFO] [SCHEDULER] FCFS embed VM vm_219 -> PM PM_7 at t=106
[2025-12-19 10:21:20] [INFO] [SCHEDULER] FCFS embed VM vm_220 -> PM PM_7 at t=106
[2025-12-19 10:21:20] [INFO] [SCHEDULER] FCFS embed VM vm_221 -> PM PM_7 at t=106
[2025-12-19 10:21:20] [INFO] [SCHEDULER] FCFS embed VM vm_222 -> PM PM_7 at t=106
[2025-12-19 10:21:20] [INFO] [STATE] VM vm_204 placed on PM PM_7
[2025-12-19 10:21:20] [INFO] [STATE] VM vm_205 placed on PM PM_7
[2025-12-19 10:21:20] [INFO] [STATE] VM vm_206 placed on PM PM_7
[2025-12-19 10:21:20] [INFO] [STATE] VM vm_207 placed on PM PM_7
[2025-12-19 10:21:20] [INFO] [STATE] VM vm_208 placed on PM PM_7
[2025-12-19 10:21:20] [INFO] [STATE] VM vm_209 placed on PM PM_7
[2025-12-19 10:21:20] [INFO] [STATE] VM vm_210 placed on PM PM_7
[2025-12-19 10:21:20] [INFO] [STATE] VM vm_211 placed on PM PM_7
[2025-12-19 10:21:20] [INFO] [STATE] VM vm_212 placed on PM PM_7
[2025-12-19 10:21:20] [INFO] [STATE] VM vm_213 placed on PM PM_7
[2025-12-19 10:21:20] [INFO] [STATE] VM vm_214 placed on PM PM_7
[2025-12-19 10:21:20] [INFO] [STATE] VM vm_215 placed on PM PM_7
[2025-12-19 10:21:20] [INFO] [STATE] VM vm_216 placed on PM PM_7
[2025-12-19 10:21:20] [INFO] [STATE] VM vm_217 placed on PM PM_7
[2025-12-19 10:21:20] [INFO] [STATE] VM vm_218 placed on PM PM_7
[2025-12-19 10:21:20] [INFO] [STATE] VM vm_219 placed on PM PM_7
[2025-12-19 10:21:20] [INFO] [STATE] VM vm_220 placed on PM PM_7
[2025-12-19 10:21:20] [INFO] [STATE] VM vm_221 placed on PM PM_7
[2025-12-19 10:21:20] [INFO] [STATE] VM vm_222 placed on PM PM_7
[2025-12-19 10:21:20] [INFO] [VM_EVENT] VM vm_223 created (pending) at t=107
[2025-12-19 10:21:20] [INFO] [VM_EVENT] VM vm_224 created (pending) at t=107
[2025-12-19 10:21:20] [INFO] [VM_EVENT] VM vm_225 created (pending) at t=107
[2025-12-19 10:21:20] [INFO] [VM_EVENT] VM vm_226 created (pending) at t=107
[2025-12-19 10:21:20] [INFO] [VM_EVENT] VM vm_227 created (pending) at t=107
[2025-12-19 10:21:20] [INFO] [VM_EVENT] VM vm_228 created (pending) at t=107
[2025-12-19 10:21:20] [INFO] [VM_EVENT] VM vm_229 created (pending) at t=107
[2025-12-19 10:21:20] [INFO] [VM_EVENT] VM vm_230 created (pending) at t=107
[2025-12-19 10:21:20] [INFO] [VM_EVENT] VM vm_231 created (pending) at t=107
[2025-12-19 10:21:20] [INFO] [VM_EVENT] VM vm_232 created (pending) at t=107
[2025-12-19 10:21:20] [INFO] [VM_EVENT] VM vm_233 created (pending) at t=107
[2025-12-19 10:21:20] [INFO] [VM_EVENT] VM vm_234 created (pending) at t=107
[2025-12-19 10:21:20] [INFO] [VM_EVENT] VM vm_235 created (pending) at t=107
[2025-12-19 10:21:20] [INFO] [VM_EVENT] VM vm_236 created (pending) at t=107
[2025-12-19 10:21:20] [INFO] [SCHEDULER] FCFS embed VM vm_223 -> PM PM_8 at t=107
[2025-12-19 10:21:20] [INFO] [SCHEDULER] FCFS embed VM vm_224 -> PM PM_8 at t=107
[2025-12-19 10:21:20] [INFO] [SCHEDULER] FCFS embed VM vm_225 -> PM PM_8 at t=107
[2025-12-19 10:21:20] [INFO] [SCHEDULER] FCFS embed VM vm_226 -> PM PM_8 at t=107
[2025-12-19 10:21:20] [INFO] [SCHEDULER] FCFS embed VM vm_227 -> PM PM_8 at t=107
[2025-12-19 10:21:20] [INFO] [SCHEDULER] FCFS embed VM vm_228 -> PM PM_8 at t=107
[2025-12-19 10:21:20] [INFO] [SCHEDULER] FCFS embed VM vm_229 -> PM PM_8 at t=107
[2025-12-19 10:21:20] [INFO] [SCHEDULER] FCFS embed VM vm_230 -> PM PM_8 at t=107
[2025-12-19 10:21:20] [INFO] [SCHEDULER] FCFS embed VM vm_231 -> PM PM_8 at t=107
[2025-12-19 10:21:20] [INFO] [SCHEDULER] FCFS embed VM vm_232 -> PM PM_8 at t=107
[2025-12-19 10:21:20] [INFO] [SCHEDULER] FCFS embed VM vm_233 -> PM PM_8 at t=107
[2025-12-19 10:21:20] [INFO] [SCHEDULER] FCFS embed VM vm_234 -> PM PM_8 at t=107
[2025-12-19 10:21:20] [INFO] [SCHEDULER] FCFS embed VM vm_235 -> PM PM_8 at t=107
[2025-12-19 10:21:20] [INFO] [SCHEDULER] FCFS embed VM vm_236 -> PM PM_8 at t=107
[2025-12-19 10:21:20] [INFO] [STATE] VM vm_223 placed on PM PM_8
[2025-12-19 10:21:20] [INFO] [STATE] VM vm_224 placed on PM PM_8
[2025-12-19 10:21:20] [INFO] [STATE] VM vm_225 placed on PM PM_8
[2025-12-19 10:21:20] [INFO] [STATE] VM vm_226 placed on PM PM_8
[2025-12-19 10:21:20] [INFO] [STATE] VM vm_227 placed on PM PM_8
[2025-12-19 10:21:20] [INFO] [STATE] VM vm_228 placed on PM PM_8
[2025-12-19 10:21:20] [INFO] [STATE] VM vm_229 placed on PM PM_8
[2025-12-19 10:21:20] [INFO] [STATE] VM vm_230 placed on PM PM_8
[2025-12-19 10:21:20] [INFO] [STATE] VM vm_231 placed on PM PM_8
[2025-12-19 10:21:20] [INFO] [STATE] VM vm_232 placed on PM PM_8
[2025-12-19 10:21:20] [INFO] [STATE] VM vm_233 placed on PM PM_8
[2025-12-19 10:21:20] [INFO] [STATE] VM vm_234 placed on PM PM_8
[2025-12-19 10:21:20] [INFO] [STATE] VM vm_235 placed on PM PM_8
[2025-12-19 10:21:20] [INFO] [STATE] VM vm_236 placed on PM PM_8
[2025-12-19 10:21:20] [INFO] [VM_EVENT] VM vm_237 created (pending) at t=108
[2025-12-19 10:21:20] [INFO] [VM_EVENT] VM vm_238 created (pending) at t=108
[2025-12-19 10:21:20] [INFO] [VM_EVENT] VM vm_239 created (pending) at t=108
[2025-12-19 10:21:20] [INFO] [VM_EVENT] VM vm_240 created (pending) at t=108
[2025-12-19 10:21:20] [INFO] [VM_EVENT] VM vm_241 created (pending) at t=108
[2025-12-19 10:21:20] [INFO] [VM_EVENT] VM vm_242 created (pending) at t=108
[2025-12-19 10:21:20] [INFO] [VM_EVENT] VM vm_243 created (pending) at t=108
[2025-12-19 10:21:20] [INFO] [VM_EVENT] VM vm_244 created (pending) at t=108
[2025-12-19 10:21:20] [INFO] [VM_EVENT] VM vm_245 created (pending) at t=108
[2025-12-19 10:21:20] [INFO] [VM_EVENT] VM vm_246 created (pending) at t=108
[2025-12-19 10:21:20] [INFO] [VM_EVENT] VM vm_247 created (pending) at t=108
[2025-12-19 10:21:20] [INFO] [VM_EVENT] VM vm_248 created (pending) at t=108
[2025-12-19 10:21:20] [INFO] [VM_EVENT] VM vm_249 created (pending) at t=108
[2025-12-19 10:21:20] [INFO] [VM_EVENT] VM vm_250 created (pending) at t=108
[2025-12-19 10:21:20] [INFO] [VM_EVENT] VM vm_251 created (pending) at t=108
[2025-12-19 10:21:20] [INFO] [SCHEDULER] FCFS embed VM vm_237 -> PM PM_6 at t=108
[2025-12-19 10:21:20] [INFO] [SCHEDULER] FCFS embed VM vm_238 -> PM PM_6 at t=108
[2025-12-19 10:21:20] [INFO] [SCHEDULER] FCFS embed VM vm_239 -> PM PM_6 at t=108
[2025-12-19 10:21:20] [INFO] [SCHEDULER] FCFS embed VM vm_240 -> PM PM_6 at t=108
[2025-12-19 10:21:20] [INFO] [SCHEDULER] FCFS embed VM vm_241 -> PM PM_6 at t=108
[2025-12-19 10:21:20] [INFO] [SCHEDULER] FCFS embed VM vm_242 -> PM PM_6 at t=108
[2025-12-19 10:21:20] [INFO] [SCHEDULER] FCFS embed VM vm_243 -> PM PM_6 at t=108
[2025-12-19 10:21:20] [INFO] [SCHEDULER] FCFS embed VM vm_244 -> PM PM_6 at t=108
[2025-12-19 10:21:20] [INFO] [SCHEDULER] FCFS embed VM vm_245 -> PM PM_6 at t=108
[2025-12-19 10:21:20] [INFO] [SCHEDULER] FCFS embed VM vm_246 -> PM PM_6 at t=108
[2025-12-19 10:21:20] [INFO] [SCHEDULER] FCFS embed VM vm_247 -> PM PM_6 at t=108
[2025-12-19 10:21:20] [INFO] [SCHEDULER] FCFS embed VM vm_248 -> PM PM_6 at t=108
[2025-12-19 10:21:20] [INFO] [SCHEDULER] FCFS embed VM vm_249 -> PM PM_6 at t=108
[2025-12-19 10:21:20] [INFO] [SCHEDULER] FCFS embed VM vm_250 -> PM PM_6 at t=108
[2025-12-19 10:21:20] [INFO] [SCHEDULER] FCFS embed VM vm_251 -> PM PM_6 at t=108
[2025-12-19 10:21:20] [INFO] [STATE] VM vm_237 placed on PM PM_6
[2025-12-19 10:21:20] [INFO] [STATE] VM vm_238 placed on PM PM_6
[2025-12-19 10:21:20] [INFO] [STATE] VM vm_239 placed on PM PM_6
[2025-12-19 10:21:20] [INFO] [STATE] VM vm_240 placed on PM PM_6
[2025-12-19 10:21:20] [INFO] [STATE] VM vm_241 placed on PM PM_6
[2025-12-19 10:21:20] [INFO] [STATE] VM vm_242 placed on PM PM_6
[2025-12-19 10:21:20] [INFO] [STATE] VM vm_243 placed on PM PM_6
[2025-12-19 10:21:20] [INFO] [STATE] VM vm_244 placed on PM PM_6
[2025-12-19 10:21:20] [INFO] [STATE] VM vm_245 placed on PM PM_6
[2025-12-19 10:21:20] [INFO] [STATE] VM vm_246 placed on PM PM_6
[2025-12-19 10:21:20] [INFO] [STATE] VM vm_247 placed on PM PM_6
[2025-12-19 10:21:20] [INFO] [STATE] VM vm_248 placed on PM PM_6
[2025-12-19 10:21:20] [INFO] [STATE] VM vm_249 placed on PM PM_6
[2025-12-19 10:21:20] [INFO] [STATE] VM vm_250 placed on PM PM_6
[2025-12-19 10:21:20] [INFO] [STATE] VM vm_251 placed on PM PM_6
[2025-12-19 10:21:20] [INFO] [VM_EVENT] VM vm_252 created (pending) at t=109
[2025-12-19 10:21:20] [INFO] [VM_EVENT] VM vm_253 created (pending) at t=109
[2025-12-19 10:21:20] [INFO] [VM_EVENT] VM vm_254 created (pending) at t=109
[2025-12-19 10:21:20] [INFO] [VM_EVENT] VM vm_255 created (pending) at t=109
[2025-12-19 10:21:20] [INFO] [VM_EVENT] VM vm_256 created (pending) at t=109
[2025-12-19 10:21:20] [INFO] [VM_EVENT] VM vm_257 created (pending) at t=109
[2025-12-19 10:21:20] [INFO] [VM_EVENT] VM vm_258 created (pending) at t=109
[2025-12-19 10:21:20] [INFO] [VM_EVENT] VM vm_259 created (pending) at t=109
[2025-12-19 10:21:20] [INFO] [VM_EVENT] VM vm_260 created (pending) at t=109
[2025-12-19 10:21:20] [INFO] [VM_EVENT] VM vm_261 created (pending) at t=109
[2025-12-19 10:21:20] [INFO] [VM_EVENT] VM vm_262 created (pending) at t=109
[2025-12-19 10:21:20] [INFO] [VM_EVENT] VM vm_263 created (pending) at t=109
[2025-12-19 10:21:20] [INFO] [VM_EVENT] VM vm_264 created (pending) at t=109
[2025-12-19 10:21:20] [INFO] [VM_EVENT] VM vm_265 created (pending) at t=109
[2025-12-19 10:21:20] [INFO] [VM_EVENT] VM vm_266 created (pending) at t=109
[2025-12-19 10:21:20] [INFO] [SCHEDULER] FCFS embed VM vm_252 -> PM PM_4 at t=109
[2025-12-19 10:21:20] [INFO] [SCHEDULER] FCFS embed VM vm_253 -> PM PM_4 at t=109
[2025-12-19 10:21:20] [INFO] [SCHEDULER] FCFS embed VM vm_254 -> PM PM_4 at t=109
[2025-12-19 10:21:20] [INFO] [SCHEDULER] FCFS embed VM vm_255 -> PM PM_4 at t=109
[2025-12-19 10:21:20] [INFO] [SCHEDULER] FCFS embed VM vm_256 -> PM PM_4 at t=109
[2025-12-19 10:21:20] [INFO] [SCHEDULER] FCFS embed VM vm_257 -> PM PM_4 at t=109
[2025-12-19 10:21:20] [INFO] [SCHEDULER] FCFS embed VM vm_258 -> PM PM_4 at t=109
[2025-12-19 10:21:20] [INFO] [SCHEDULER] FCFS embed VM vm_259 -> PM PM_4 at t=109
[2025-12-19 10:21:20] [INFO] [SCHEDULER] FCFS embed VM vm_260 -> PM PM_4 at t=109
[2025-12-19 10:21:20] [INFO] [SCHEDULER] FCFS embed VM vm_261 -> PM PM_4 at t=109
[2025-12-19 10:21:20] [INFO] [SCHEDULER] FCFS embed VM vm_262 -> PM PM_4 at t=109
[2025-12-19 10:21:20] [INFO] [SCHEDULER] FCFS embed VM vm_263 -> PM PM_4 at t=109
[2025-12-19 10:21:20] [INFO] [SCHEDULER] FCFS embed VM vm_264 -> PM PM_4 at t=109
[2025-12-19 10:21:20] [INFO] [SCHEDULER] FCFS embed VM vm_265 -> PM PM_4 at t=109
[2025-12-19 10:21:20] [INFO] [SCHEDULER] FCFS embed VM vm_266 -> PM PM_4 at t=109
[2025-12-19 10:21:20] [INFO] [STATE] VM vm_252 placed on PM PM_4
[2025-12-19 10:21:20] [INFO] [STATE] VM vm_253 placed on PM PM_4
[2025-12-19 10:21:20] [INFO] [STATE] VM vm_254 placed on PM PM_4
[2025-12-19 10:21:20] [INFO] [STATE] VM vm_255 placed on PM PM_4
[2025-12-19 10:21:20] [INFO] [STATE] VM vm_256 placed on PM PM_4
[2025-12-19 10:21:20] [INFO] [STATE] VM vm_257 placed on PM PM_4
[2025-12-19 10:21:20] [INFO] [STATE] VM vm_258 placed on PM PM_4
[2025-12-19 10:21:20] [INFO] [STATE] VM vm_259 placed on PM PM_4
[2025-12-19 10:21:20] [INFO] [STATE] VM vm_260 placed on PM PM_4
[2025-12-19 10:21:20] [INFO] [STATE] VM vm_261 placed on PM PM_4
[2025-12-19 10:21:20] [INFO] [STATE] VM vm_262 placed on PM PM_4
[2025-12-19 10:21:20] [INFO] [STATE] VM vm_263 placed on PM PM_4
[2025-12-19 10:21:20] [INFO] [STATE] VM vm_264 placed on PM PM_4
[2025-12-19 10:21:20] [INFO] [STATE] VM vm_265 placed on PM PM_4
[2025-12-19 10:21:20] [INFO] [STATE] VM vm_266 placed on PM PM_4
[2025-12-19 10:21:20] [INFO] [VM_EVENT] VM vm_267 created (pending) at t=110
[2025-12-19 10:21:20] [INFO] [VM_EVENT] VM vm_268 created (pending) at t=110
[2025-12-19 10:21:20] [INFO] [VM_EVENT] VM vm_269 created (pending) at t=110
[2025-12-19 10:21:20] [INFO] [VM_EVENT] VM vm_270 created (pending) at t=110
[2025-12-19 10:21:20] [INFO] [VM_EVENT] VM vm_271 created (pending) at t=110
[2025-12-19 10:21:20] [INFO] [VM_EVENT] VM vm_272 created (pending) at t=110
[2025-12-19 10:21:20] [INFO] [VM_EVENT] VM vm_273 created (pending) at t=110
[2025-12-19 10:21:20] [INFO] [VM_EVENT] VM vm_274 created (pending) at t=110
[2025-12-19 10:21:20] [INFO] [VM_EVENT] VM vm_275 created (pending) at t=110
[2025-12-19 10:21:20] [INFO] [VM_EVENT] VM vm_276 created (pending) at t=110
[2025-12-19 10:21:20] [INFO] [VM_EVENT] VM vm_277 created (pending) at t=110
[2025-12-19 10:21:20] [INFO] [VM_EVENT] VM vm_278 created (pending) at t=110
[2025-12-19 10:21:20] [INFO] [VM_EVENT] VM vm_279 created (pending) at t=110
[2025-12-19 10:21:20] [INFO] [VM_EVENT] VM vm_280 created (pending) at t=110
[2025-12-19 10:21:20] [INFO] [VM_EVENT] VM vm_281 created (pending) at t=110
[2025-12-19 10:21:20] [INFO] [VM_EVENT] VM vm_282 created (pending) at t=110
[2025-12-19 10:21:20] [INFO] [SCHEDULER] FCFS embed VM vm_267 -> PM PM_8 at t=110
[2025-12-19 10:21:20] [INFO] [SCHEDULER] FCFS embed VM vm_268 -> PM PM_8 at t=110
[2025-12-19 10:21:20] [INFO] [SCHEDULER] FCFS embed VM vm_269 -> PM PM_8 at t=110
[2025-12-19 10:21:20] [INFO] [SCHEDULER] FCFS embed VM vm_270 -> PM PM_8 at t=110
[2025-12-19 10:21:20] [INFO] [SCHEDULER] FCFS embed VM vm_271 -> PM PM_8 at t=110
[2025-12-19 10:21:20] [INFO] [SCHEDULER] FCFS embed VM vm_272 -> PM PM_8 at t=110
[2025-12-19 10:21:20] [INFO] [SCHEDULER] FCFS embed VM vm_273 -> PM PM_8 at t=110
[2025-12-19 10:21:20] [INFO] [SCHEDULER] FCFS embed VM vm_274 -> PM PM_8 at t=110
[2025-12-19 10:21:20] [INFO] [SCHEDULER] FCFS embed VM vm_275 -> PM PM_8 at t=110
[2025-12-19 10:21:20] [INFO] [SCHEDULER] FCFS embed VM vm_276 -> PM PM_8 at t=110
[2025-12-19 10:21:20] [INFO] [SCHEDULER] FCFS embed VM vm_277 -> PM PM_8 at t=110
[2025-12-19 10:21:20] [INFO] [SCHEDULER] FCFS embed VM vm_278 -> PM PM_8 at t=110
[2025-12-19 10:21:20] [INFO] [SCHEDULER] FCFS embed VM vm_279 -> PM PM_8 at t=110
[2025-12-19 10:21:20] [INFO] [SCHEDULER] FCFS embed VM vm_280 -> PM PM_8 at t=110
[2025-12-19 10:21:20] [INFO] [SCHEDULER] FCFS embed VM vm_281 -> PM PM_8 at t=110
[2025-12-19 10:21:20] [INFO] [SCHEDULER] FCFS embed VM vm_282 -> PM PM_8 at t=110
[2025-12-19 10:21:20] [INFO] [STATE] VM vm_267 placed on PM PM_8
[2025-12-19 10:21:20] [INFO] [STATE] VM vm_268 placed on PM PM_8
[2025-12-19 10:21:20] [INFO] [STATE] VM vm_269 placed on PM PM_8
[2025-12-19 10:21:20] [INFO] [STATE] VM vm_270 placed on PM PM_8
[2025-12-19 10:21:20] [INFO] [STATE] VM vm_271 placed on PM PM_8
[2025-12-19 10:21:20] [INFO] [STATE] VM vm_272 placed on PM PM_8
[2025-12-19 10:21:20] [INFO] [STATE] VM vm_273 placed on PM PM_8
[2025-12-19 10:21:20] [INFO] [STATE] VM vm_274 placed on PM PM_8
[2025-12-19 10:21:20] [INFO] [STATE] VM vm_275 placed on PM PM_8
[2025-12-19 10:21:20] [INFO] [STATE] VM vm_276 placed on PM PM_8
[2025-12-19 10:21:20] [INFO] [STATE] VM vm_277 placed on PM PM_8
[2025-12-19 10:21:20] [INFO] [STATE] VM vm_278 placed on PM PM_8
[2025-12-19 10:21:20] [INFO] [STATE] VM vm_279 placed on PM PM_8
[2025-12-19 10:21:20] [INFO] [STATE] VM vm_280 placed on PM PM_8
[2025-12-19 10:21:20] [INFO] [STATE] VM vm_281 placed on PM PM_8
[2025-12-19 10:21:20] [INFO] [STATE] VM vm_282 placed on PM PM_8
[2025-12-19 10:21:20] [INFO] [VM_EVENT] VM vm_283 created (pending) at t=111
[2025-12-19 10:21:20] [INFO] [VM_EVENT] VM vm_284 created (pending) at t=111
[2025-12-19 10:21:20] [INFO] [VM_EVENT] VM vm_285 created (pending) at t=111
[2025-12-19 10:21:20] [INFO] [VM_EVENT] VM vm_286 created (pending) at t=111
[2025-12-19 10:21:20] [INFO] [VM_EVENT] VM vm_287 created (pending) at t=111
[2025-12-19 10:21:20] [INFO] [VM_EVENT] VM vm_288 created (pending) at t=111
[2025-12-19 10:21:20] [INFO] [VM_EVENT] VM vm_289 created (pending) at t=111
[2025-12-19 10:21:20] [INFO] [VM_EVENT] VM vm_290 created (pending) at t=111
[2025-12-19 10:21:20] [INFO] [VM_EVENT] VM vm_291 created (pending) at t=111
[2025-12-19 10:21:20] [INFO] [VM_EVENT] VM vm_292 created (pending) at t=111
[2025-12-19 10:21:20] [INFO] [VM_EVENT] VM vm_293 created (pending) at t=111
[2025-12-19 10:21:20] [INFO] [VM_EVENT] VM vm_294 created (pending) at t=111
[2025-12-19 10:21:20] [INFO] [VM_EVENT] VM vm_295 created (pending) at t=111
[2025-12-19 10:21:20] [INFO] [VM_EVENT] VM vm_296 created (pending) at t=111
[2025-12-19 10:21:20] [INFO] [VM_EVENT] VM vm_297 created (pending) at t=111
[2025-12-19 10:21:20] [INFO] [VM_EVENT] VM vm_298 created (pending) at t=111
[2025-12-19 10:21:20] [INFO] [SCHEDULER] FCFS embed VM vm_283 -> PM PM_4 at t=111
[2025-12-19 10:21:20] [INFO] [SCHEDULER] FCFS embed VM vm_284 -> PM PM_4 at t=111
[2025-12-19 10:21:20] [INFO] [SCHEDULER] FCFS embed VM vm_285 -> PM PM_4 at t=111
[2025-12-19 10:21:20] [INFO] [SCHEDULER] FCFS embed VM vm_286 -> PM PM_4 at t=111
[2025-12-19 10:21:20] [INFO] [SCHEDULER] FCFS embed VM vm_287 -> PM PM_4 at t=111
[2025-12-19 10:21:20] [INFO] [SCHEDULER] FCFS embed VM vm_288 -> PM PM_4 at t=111
[2025-12-19 10:21:20] [INFO] [SCHEDULER] FCFS embed VM vm_289 -> PM PM_4 at t=111
[2025-12-19 10:21:20] [INFO] [SCHEDULER] FCFS embed VM vm_290 -> PM PM_4 at t=111
[2025-12-19 10:21:20] [INFO] [SCHEDULER] FCFS embed VM vm_291 -> PM PM_4 at t=111
[2025-12-19 10:21:20] [INFO] [SCHEDULER] FCFS embed VM vm_292 -> PM PM_4 at t=111
[2025-12-19 10:21:20] [INFO] [SCHEDULER] FCFS embed VM vm_293 -> PM PM_4 at t=111
[2025-12-19 10:21:20] [INFO] [SCHEDULER] FCFS embed VM vm_294 -> PM PM_4 at t=111
[2025-12-19 10:21:20] [INFO] [SCHEDULER] FCFS embed VM vm_295 -> PM PM_4 at t=111
[2025-12-19 10:21:20] [INFO] [SCHEDULER] FCFS embed VM vm_296 -> PM PM_4 at t=111
[2025-12-19 10:21:20] [INFO] [SCHEDULER] FCFS embed VM vm_297 -> PM PM_4 at t=111
[2025-12-19 10:21:20] [INFO] [SCHEDULER] FCFS embed VM vm_298 -> PM PM_4 at t=111
[2025-12-19 10:21:20] [INFO] [STATE] VM vm_283 placed on PM PM_4
[2025-12-19 10:21:20] [INFO] [STATE] VM vm_284 placed on PM PM_4
[2025-12-19 10:21:20] [INFO] [STATE] VM vm_285 placed on PM PM_4
[2025-12-19 10:21:20] [INFO] [STATE] VM vm_286 placed on PM PM_4
[2025-12-19 10:21:20] [INFO] [STATE] VM vm_287 placed on PM PM_4
[2025-12-19 10:21:20] [INFO] [STATE] VM vm_288 placed on PM PM_4
[2025-12-19 10:21:20] [INFO] [STATE] VM vm_289 placed on PM PM_4
[2025-12-19 10:21:20] [INFO] [STATE] VM vm_290 placed on PM PM_4
[2025-12-19 10:21:20] [INFO] [STATE] VM vm_291 placed on PM PM_4
[2025-12-19 10:21:20] [INFO] [STATE] VM vm_292 placed on PM PM_4
[2025-12-19 10:21:20] [INFO] [STATE] VM vm_293 placed on PM PM_4
[2025-12-19 10:21:20] [INFO] [STATE] VM vm_294 placed on PM PM_4
[2025-12-19 10:21:20] [INFO] [STATE] VM vm_295 placed on PM PM_4
[2025-12-19 10:21:20] [INFO] [STATE] VM vm_296 placed on PM PM_4
[2025-12-19 10:21:20] [INFO] [STATE] VM vm_297 placed on PM PM_4
[2025-12-19 10:21:20] [INFO] [STATE] VM vm_298 placed on PM PM_4
[2025-12-19 10:21:20] [INFO] [VM_EVENT] VM vm_299 created (pending) at t=112
[2025-12-19 10:21:20] [INFO] [VM_EVENT] VM vm_300 created (pending) at t=112
[2025-12-19 10:21:20] [INFO] [VM_EVENT] VM vm_301 created (pending) at t=112
[2025-12-19 10:21:20] [INFO] [VM_EVENT] VM vm_302 created (pending) at t=112
[2025-12-19 10:21:20] [INFO] [VM_EVENT] VM vm_303 created (pending) at t=112
[2025-12-19 10:21:20] [INFO] [VM_EVENT] VM vm_304 created (pending) at t=112
[2025-12-19 10:21:20] [INFO] [VM_EVENT] VM vm_305 created (pending) at t=112
[2025-12-19 10:21:20] [INFO] [VM_EVENT] VM vm_306 created (pending) at t=112
[2025-12-19 10:21:20] [INFO] [VM_EVENT] VM vm_307 created (pending) at t=112
[2025-12-19 10:21:20] [INFO] [VM_EVENT] VM vm_308 created (pending) at t=112
[2025-12-19 10:21:20] [INFO] [VM_EVENT] VM vm_309 created (pending) at t=112
[2025-12-19 10:21:20] [INFO] [VM_EVENT] VM vm_310 created (pending) at t=112
[2025-12-19 10:21:20] [INFO] [VM_EVENT] VM vm_311 created (pending) at t=112
[2025-12-19 10:21:20] [INFO] [VM_EVENT] VM vm_312 created (pending) at t=112
[2025-12-19 10:21:20] [INFO] [VM_EVENT] VM vm_313 created (pending) at t=112
[2025-12-19 10:21:20] [INFO] [VM_EVENT] VM vm_314 created (pending) at t=112
[2025-12-19 10:21:20] [INFO] [VM_EVENT] VM vm_315 created (pending) at t=112
[2025-12-19 10:21:20] [INFO] [VM_EVENT] VM vm_316 created (pending) at t=112
[2025-12-19 10:21:20] [INFO] [VM_EVENT] VM vm_317 created (pending) at t=112
[2025-12-19 10:21:20] [INFO] [VM_EVENT] VM vm_318 created (pending) at t=112
[2025-12-19 10:21:20] [INFO] [VM_EVENT] VM vm_319 created (pending) at t=112
[2025-12-19 10:21:20] [INFO] [VM_EVENT] VM vm_320 created (pending) at t=112
[2025-12-19 10:21:20] [INFO] [VM_EVENT] VM vm_321 created (pending) at t=112
[2025-12-19 10:21:20] [INFO] [SCHEDULER] FCFS embed VM vm_299 -> PM PM_3 at t=112
[2025-12-19 10:21:20] [INFO] [SCHEDULER] FCFS embed VM vm_300 -> PM PM_3 at t=112
[2025-12-19 10:21:20] [INFO] [SCHEDULER] FCFS embed VM vm_301 -> PM PM_3 at t=112
[2025-12-19 10:21:20] [INFO] [SCHEDULER] FCFS embed VM vm_302 -> PM PM_3 at t=112
[2025-12-19 10:21:20] [INFO] [SCHEDULER] FCFS embed VM vm_303 -> PM PM_3 at t=112
[2025-12-19 10:21:20] [INFO] [SCHEDULER] FCFS embed VM vm_304 -> PM PM_3 at t=112
[2025-12-19 10:21:20] [INFO] [SCHEDULER] FCFS embed VM vm_305 -> PM PM_3 at t=112
[2025-12-19 10:21:20] [INFO] [SCHEDULER] FCFS embed VM vm_306 -> PM PM_3 at t=112
[2025-12-19 10:21:20] [INFO] [SCHEDULER] FCFS embed VM vm_307 -> PM PM_3 at t=112
[2025-12-19 10:21:20] [INFO] [SCHEDULER] FCFS embed VM vm_308 -> PM PM_3 at t=112
[2025-12-19 10:21:20] [INFO] [SCHEDULER] FCFS embed VM vm_309 -> PM PM_3 at t=112
[2025-12-19 10:21:20] [INFO] [SCHEDULER] FCFS embed VM vm_310 -> PM PM_3 at t=112
[2025-12-19 10:21:20] [INFO] [SCHEDULER] FCFS embed VM vm_311 -> PM PM_3 at t=112
[2025-12-19 10:21:20] [INFO] [SCHEDULER] FCFS embed VM vm_312 -> PM PM_3 at t=112
[2025-12-19 10:21:20] [INFO] [SCHEDULER] FCFS embed VM vm_313 -> PM PM_3 at t=112
[2025-12-19 10:21:20] [INFO] [SCHEDULER] FCFS embed VM vm_314 -> PM PM_3 at t=112
[2025-12-19 10:21:20] [INFO] [SCHEDULER] FCFS embed VM vm_315 -> PM PM_3 at t=112
[2025-12-19 10:21:20] [INFO] [SCHEDULER] FCFS embed VM vm_316 -> PM PM_3 at t=112
[2025-12-19 10:21:20] [INFO] [SCHEDULER] FCFS embed VM vm_317 -> PM PM_3 at t=112
[2025-12-19 10:21:20] [INFO] [SCHEDULER] FCFS embed VM vm_318 -> PM PM_3 at t=112
[2025-12-19 10:21:20] [INFO] [SCHEDULER] FCFS embed VM vm_319 -> PM PM_3 at t=112
[2025-12-19 10:21:20] [INFO] [SCHEDULER] FCFS embed VM vm_320 -> PM PM_3 at t=112
[2025-12-19 10:21:20] [INFO] [SCHEDULER] FCFS embed VM vm_321 -> PM PM_3 at t=112
[2025-12-19 10:21:20] [INFO] [STATE] VM vm_299 placed on PM PM_3
[2025-12-19 10:21:20] [INFO] [STATE] VM vm_300 placed on PM PM_3
[2025-12-19 10:21:20] [INFO] [STATE] VM vm_301 placed on PM PM_3
[2025-12-19 10:21:20] [INFO] [STATE] VM vm_302 placed on PM PM_3
[2025-12-19 10:21:20] [INFO] [STATE] VM vm_303 placed on PM PM_3
[2025-12-19 10:21:20] [INFO] [STATE] VM vm_304 placed on PM PM_3
[2025-12-19 10:21:20] [INFO] [STATE] VM vm_305 placed on PM PM_3
[2025-12-19 10:21:20] [INFO] [STATE] VM vm_306 placed on PM PM_3
[2025-12-19 10:21:20] [INFO] [STATE] VM vm_307 placed on PM PM_3
[2025-12-19 10:21:20] [INFO] [STATE] VM vm_308 placed on PM PM_3
[2025-12-19 10:21:20] [INFO] [STATE] VM vm_309 placed on PM PM_3
[2025-12-19 10:21:20] [INFO] [STATE] VM vm_310 placed on PM PM_3
[2025-12-19 10:21:20] [INFO] [STATE] VM vm_311 placed on PM PM_3
[2025-12-19 10:21:20] [INFO] [STATE] VM vm_312 placed on PM PM_3
[2025-12-19 10:21:20] [INFO] [STATE] VM vm_313 placed on PM PM_3
[2025-12-19 10:21:20] [INFO] [STATE] VM vm_314 placed on PM PM_3
[2025-12-19 10:21:20] [INFO] [STATE] VM vm_315 placed on PM PM_3
[2025-12-19 10:21:20] [INFO] [STATE] VM vm_316 placed on PM PM_3
[2025-12-19 10:21:20] [INFO] [STATE] VM vm_317 placed on PM PM_3
[2025-12-19 10:21:20] [INFO] [STATE] VM vm_318 placed on PM PM_3
[2025-12-19 10:21:20] [INFO] [STATE] VM vm_319 placed on PM PM_3
[2025-12-19 10:21:20] [INFO] [STATE] VM vm_320 placed on PM PM_3
[2025-12-19 10:21:20] [INFO] [STATE] VM vm_321 placed on PM PM_3
[2025-12-19 10:21:20] [INFO] [VM_EVENT] VM vm_322 created (pending) at t=113
[2025-12-19 10:21:20] [INFO] [VM_EVENT] VM vm_323 created (pending) at t=113
[2025-12-19 10:21:20] [INFO] [VM_EVENT] VM vm_324 created (pending) at t=113
[2025-12-19 10:21:20] [INFO] [VM_EVENT] VM vm_325 created (pending) at t=113
[2025-12-19 10:21:20] [INFO] [VM_EVENT] VM vm_326 created (pending) at t=113
[2025-12-19 10:21:20] [INFO] [VM_EVENT] VM vm_327 created (pending) at t=113
[2025-12-19 10:21:20] [INFO] [VM_EVENT] VM vm_328 created (pending) at t=113
[2025-12-19 10:21:20] [INFO] [VM_EVENT] VM vm_329 created (pending) at t=113
[2025-12-19 10:21:20] [INFO] [VM_EVENT] VM vm_330 created (pending) at t=113
[2025-12-19 10:21:20] [INFO] [VM_EVENT] VM vm_331 created (pending) at t=113
[2025-12-19 10:21:20] [INFO] [VM_EVENT] VM vm_332 created (pending) at t=113
[2025-12-19 10:21:20] [INFO] [VM_EVENT] VM vm_333 created (pending) at t=113
[2025-12-19 10:21:20] [INFO] [VM_EVENT] VM vm_334 created (pending) at t=113
[2025-12-19 10:21:20] [INFO] [SCHEDULER] FCFS embed VM vm_322 -> PM PM_4 at t=113
[2025-12-19 10:21:20] [INFO] [SCHEDULER] FCFS embed VM vm_323 -> PM PM_4 at t=113
[2025-12-19 10:21:20] [INFO] [SCHEDULER] FCFS embed VM vm_324 -> PM PM_4 at t=113
[2025-12-19 10:21:20] [INFO] [SCHEDULER] FCFS embed VM vm_325 -> PM PM_4 at t=113
[2025-12-19 10:21:20] [INFO] [SCHEDULER] FCFS embed VM vm_326 -> PM PM_4 at t=113
[2025-12-19 10:21:20] [INFO] [SCHEDULER] FCFS embed VM vm_327 -> PM PM_4 at t=113
[2025-12-19 10:21:20] [INFO] [SCHEDULER] FCFS embed VM vm_328 -> PM PM_4 at t=113
[2025-12-19 10:21:20] [INFO] [SCHEDULER] FCFS embed VM vm_329 -> PM PM_4 at t=113
[2025-12-19 10:21:20] [INFO] [SCHEDULER] FCFS embed VM vm_330 -> PM PM_4 at t=113
[2025-12-19 10:21:20] [INFO] [SCHEDULER] FCFS embed VM vm_331 -> PM PM_4 at t=113
[2025-12-19 10:21:20] [INFO] [SCHEDULER] FCFS embed VM vm_332 -> PM PM_4 at t=113
[2025-12-19 10:21:20] [INFO] [SCHEDULER] FCFS embed VM vm_333 -> PM PM_4 at t=113
[2025-12-19 10:21:20] [INFO] [SCHEDULER] FCFS embed VM vm_334 -> PM PM_4 at t=113
[2025-12-19 10:21:20] [INFO] [STATE] VM vm_322 placed on PM PM_4
[2025-12-19 10:21:20] [INFO] [STATE] VM vm_323 placed on PM PM_4
[2025-12-19 10:21:20] [INFO] [STATE] VM vm_324 placed on PM PM_4
[2025-12-19 10:21:20] [INFO] [STATE] VM vm_325 placed on PM PM_4
[2025-12-19 10:21:20] [INFO] [STATE] VM vm_326 placed on PM PM_4
[2025-12-19 10:21:20] [INFO] [STATE] VM vm_327 placed on PM PM_4
[2025-12-19 10:21:20] [INFO] [STATE] VM vm_328 placed on PM PM_4
[2025-12-19 10:21:20] [INFO] [STATE] VM vm_329 placed on PM PM_4
[2025-12-19 10:21:20] [INFO] [STATE] VM vm_330 placed on PM PM_4
[2025-12-19 10:21:20] [INFO] [STATE] VM vm_331 placed on PM PM_4
[2025-12-19 10:21:20] [INFO] [STATE] VM vm_332 placed on PM PM_4
[2025-12-19 10:21:20] [INFO] [STATE] VM vm_333 placed on PM PM_4
[2025-12-19 10:21:20] [INFO] [STATE] VM vm_334 placed on PM PM_4
[2025-12-19 10:21:20] [INFO] [VM_EVENT] VM vm_335 created (pending) at t=114
[2025-12-19 10:21:20] [INFO] [VM_EVENT] VM vm_336 created (pending) at t=114
[2025-12-19 10:21:20] [INFO] [VM_EVENT] VM vm_337 created (pending) at t=114
[2025-12-19 10:21:20] [INFO] [VM_EVENT] VM vm_338 created (pending) at t=114
[2025-12-19 10:21:20] [INFO] [VM_EVENT] VM vm_339 created (pending) at t=114
[2025-12-19 10:21:20] [INFO] [VM_EVENT] VM vm_340 created (pending) at t=114
[2025-12-19 10:21:20] [INFO] [VM_EVENT] VM vm_341 created (pending) at t=114
[2025-12-19 10:21:20] [INFO] [VM_EVENT] VM vm_342 created (pending) at t=114
[2025-12-19 10:21:20] [INFO] [VM_EVENT] VM vm_343 created (pending) at t=114
[2025-12-19 10:21:20] [INFO] [VM_EVENT] VM vm_344 created (pending) at t=114
[2025-12-19 10:21:20] [INFO] [VM_EVENT] VM vm_345 created (pending) at t=114
[2025-12-19 10:21:20] [INFO] [VM_EVENT] VM vm_346 created (pending) at t=114
[2025-12-19 10:21:20] [INFO] [VM_EVENT] VM vm_347 created (pending) at t=114
[2025-12-19 10:21:20] [INFO] [SCHEDULER] FCFS embed VM vm_335 -> PM PM_6 at t=114
[2025-12-19 10:21:20] [INFO] [SCHEDULER] FCFS embed VM vm_336 -> PM PM_6 at t=114
[2025-12-19 10:21:20] [INFO] [SCHEDULER] FCFS embed VM vm_337 -> PM PM_6 at t=114
[2025-12-19 10:21:20] [INFO] [SCHEDULER] FCFS embed VM vm_338 -> PM PM_6 at t=114
[2025-12-19 10:21:20] [INFO] [SCHEDULER] FCFS embed VM vm_339 -> PM PM_6 at t=114
[2025-12-19 10:21:20] [INFO] [SCHEDULER] FCFS embed VM vm_340 -> PM PM_6 at t=114
[2025-12-19 10:21:20] [INFO] [SCHEDULER] FCFS embed VM vm_341 -> PM PM_6 at t=114
[2025-12-19 10:21:20] [INFO] [SCHEDULER] FCFS embed VM vm_342 -> PM PM_6 at t=114
[2025-12-19 10:21:20] [INFO] [SCHEDULER] FCFS embed VM vm_343 -> PM PM_6 at t=114
[2025-12-19 10:21:20] [INFO] [SCHEDULER] FCFS embed VM vm_344 -> PM PM_6 at t=114
[2025-12-19 10:21:20] [INFO] [SCHEDULER] FCFS embed VM vm_345 -> PM PM_6 at t=114
[2025-12-19 10:21:20] [INFO] [SCHEDULER] FCFS embed VM vm_346 -> PM PM_6 at t=114
[2025-12-19 10:21:20] [INFO] [SCHEDULER] FCFS embed VM vm_347 -> PM PM_6 at t=114
[2025-12-19 10:21:20] [INFO] [STATE] VM vm_335 placed on PM PM_6
[2025-12-19 10:21:20] [INFO] [STATE] VM vm_336 placed on PM PM_6
[2025-12-19 10:21:20] [INFO] [STATE] VM vm_337 placed on PM PM_6
[2025-12-19 10:21:20] [INFO] [STATE] VM vm_338 placed on PM PM_6
[2025-12-19 10:21:20] [INFO] [STATE] VM vm_339 placed on PM PM_6
[2025-12-19 10:21:20] [INFO] [STATE] VM vm_340 placed on PM PM_6
[2025-12-19 10:21:20] [INFO] [STATE] VM vm_341 placed on PM PM_6
[2025-12-19 10:21:20] [INFO] [STATE] VM vm_342 placed on PM PM_6
[2025-12-19 10:21:20] [INFO] [STATE] VM vm_343 placed on PM PM_6
[2025-12-19 10:21:20] [INFO] [STATE] VM vm_344 placed on PM PM_6
[2025-12-19 10:21:20] [INFO] [STATE] VM vm_345 placed on PM PM_6
[2025-12-19 10:21:20] [INFO] [STATE] VM vm_346 placed on PM PM_6
[2025-12-19 10:21:20] [INFO] [STATE] VM vm_347 placed on PM PM_6
[2025-12-19 10:21:20] [INFO] [VM_EVENT] VM vm_348 created (pending) at t=115
[2025-12-19 10:21:20] [INFO] [VM_EVENT] VM vm_349 created (pending) at t=115
[2025-12-19 10:21:20] [INFO] [VM_EVENT] VM vm_350 created (pending) at t=115
[2025-12-19 10:21:20] [INFO] [VM_EVENT] VM vm_351 created (pending) at t=115
[2025-12-19 10:21:20] [INFO] [VM_EVENT] VM vm_352 created (pending) at t=115
[2025-12-19 10:21:20] [INFO] [VM_EVENT] VM vm_353 created (pending) at t=115
[2025-12-19 10:21:20] [INFO] [VM_EVENT] VM vm_354 created (pending) at t=115
[2025-12-19 10:21:20] [INFO] [VM_EVENT] VM vm_355 created (pending) at t=115
[2025-12-19 10:21:20] [INFO] [VM_EVENT] VM vm_356 created (pending) at t=115
[2025-12-19 10:21:20] [INFO] [VM_EVENT] VM vm_357 created (pending) at t=115
[2025-12-19 10:21:20] [INFO] [VM_EVENT] VM vm_358 created (pending) at t=115
[2025-12-19 10:21:20] [INFO] [VM_EVENT] VM vm_359 created (pending) at t=115
[2025-12-19 10:21:20] [INFO] [VM_EVENT] VM vm_360 created (pending) at t=115
[2025-12-19 10:21:20] [INFO] [VM_EVENT] VM vm_361 created (pending) at t=115
[2025-12-19 10:21:20] [INFO] [VM_EVENT] VM vm_362 created (pending) at t=115
[2025-12-19 10:21:20] [INFO] [VM_EVENT] VM vm_363 created (pending) at t=115
[2025-12-19 10:21:20] [INFO] [VM_EVENT] VM vm_364 created (pending) at t=115
[2025-12-19 10:21:20] [INFO] [VM_EVENT] VM vm_365 created (pending) at t=115
[2025-12-19 10:21:20] [INFO] [VM_EVENT] VM vm_366 created (pending) at t=115
[2025-12-19 10:21:20] [INFO] [VM_EVENT] VM vm_367 created (pending) at t=115
[2025-12-19 10:21:20] [INFO] [VM_EVENT] VM vm_368 created (pending) at t=115
[2025-12-19 10:21:20] [INFO] [VM_EVENT] VM vm_369 created (pending) at t=115
[2025-12-19 10:21:20] [INFO] [VM_EVENT] VM vm_370 created (pending) at t=115
[2025-12-19 10:21:20] [INFO] [VM_EVENT] VM vm_371 created (pending) at t=115
[2025-12-19 10:21:20] [INFO] [VM_EVENT] VM vm_372 created (pending) at t=115
[2025-12-19 10:21:20] [INFO] [VM_EVENT] VM vm_373 created (pending) at t=115
[2025-12-19 10:21:20] [INFO] [VM_EVENT] VM vm_374 created (pending) at t=115
[2025-12-19 10:21:20] [INFO] [VM_EVENT] VM vm_375 created (pending) at t=115
[2025-12-19 10:21:20] [INFO] [VM_EVENT] VM vm_376 created (pending) at t=115
[2025-12-19 10:21:20] [INFO] [VM_EVENT] VM vm_377 created (pending) at t=115
[2025-12-19 10:21:20] [INFO] [VM_EVENT] VM vm_378 created (pending) at t=115
[2025-12-19 10:21:20] [INFO] [VM_EVENT] VM vm_379 created (pending) at t=115
[2025-12-19 10:21:20] [INFO] [SCHEDULER] FCFS embed VM vm_348 -> PM PM_1 at t=115
[2025-12-19 10:21:20] [INFO] [SCHEDULER] FCFS embed VM vm_349 -> PM PM_1 at t=115
[2025-12-19 10:21:20] [INFO] [SCHEDULER] FCFS embed VM vm_350 -> PM PM_1 at t=115
[2025-12-19 10:21:20] [INFO] [SCHEDULER] FCFS embed VM vm_351 -> PM PM_1 at t=115
[2025-12-19 10:21:20] [INFO] [SCHEDULER] FCFS embed VM vm_352 -> PM PM_1 at t=115
[2025-12-19 10:21:20] [INFO] [SCHEDULER] FCFS embed VM vm_353 -> PM PM_1 at t=115
[2025-12-19 10:21:20] [INFO] [SCHEDULER] FCFS embed VM vm_354 -> PM PM_1 at t=115
[2025-12-19 10:21:20] [INFO] [SCHEDULER] FCFS embed VM vm_355 -> PM PM_1 at t=115
[2025-12-19 10:21:20] [INFO] [SCHEDULER] FCFS embed VM vm_356 -> PM PM_1 at t=115
[2025-12-19 10:21:20] [INFO] [SCHEDULER] FCFS embed VM vm_357 -> PM PM_1 at t=115
[2025-12-19 10:21:20] [INFO] [SCHEDULER] FCFS embed VM vm_358 -> PM PM_1 at t=115
[2025-12-19 10:21:20] [INFO] [SCHEDULER] FCFS embed VM vm_359 -> PM PM_1 at t=115
[2025-12-19 10:21:20] [INFO] [SCHEDULER] FCFS embed VM vm_360 -> PM PM_1 at t=115
[2025-12-19 10:21:20] [INFO] [SCHEDULER] FCFS embed VM vm_361 -> PM PM_1 at t=115
[2025-12-19 10:21:20] [INFO] [SCHEDULER] FCFS embed VM vm_362 -> PM PM_1 at t=115
[2025-12-19 10:21:20] [INFO] [SCHEDULER] FCFS embed VM vm_363 -> PM PM_1 at t=115
[2025-12-19 10:21:20] [INFO] [SCHEDULER] FCFS embed VM vm_364 -> PM PM_1 at t=115
[2025-12-19 10:21:20] [INFO] [SCHEDULER] FCFS embed VM vm_365 -> PM PM_1 at t=115
[2025-12-19 10:21:20] [INFO] [SCHEDULER] FCFS embed VM vm_366 -> PM PM_1 at t=115
[2025-12-19 10:21:20] [INFO] [SCHEDULER] FCFS embed VM vm_367 -> PM PM_1 at t=115
[2025-12-19 10:21:20] [INFO] [SCHEDULER] FCFS embed VM vm_368 -> PM PM_1 at t=115
[2025-12-19 10:21:20] [INFO] [SCHEDULER] FCFS embed VM vm_369 -> PM PM_1 at t=115
[2025-12-19 10:21:20] [INFO] [SCHEDULER] FCFS embed VM vm_370 -> PM PM_1 at t=115
[2025-12-19 10:21:20] [INFO] [SCHEDULER] FCFS embed VM vm_371 -> PM PM_1 at t=115
[2025-12-19 10:21:20] [INFO] [SCHEDULER] FCFS embed VM vm_372 -> PM PM_1 at t=115
[2025-12-19 10:21:20] [INFO] [SCHEDULER] FCFS embed VM vm_373 -> PM PM_1 at t=115
[2025-12-19 10:21:20] [INFO] [SCHEDULER] FCFS embed VM vm_374 -> PM PM_1 at t=115
[2025-12-19 10:21:20] [INFO] [SCHEDULER] FCFS embed VM vm_375 -> PM PM_1 at t=115
[2025-12-19 10:21:20] [INFO] [SCHEDULER] FCFS embed VM vm_376 -> PM PM_1 at t=115
[2025-12-19 10:21:20] [INFO] [SCHEDULER] FCFS embed VM vm_377 -> PM PM_1 at t=115
[2025-12-19 10:21:20] [INFO] [SCHEDULER] FCFS embed VM vm_378 -> PM PM_1 at t=115
[2025-12-19 10:21:20] [INFO] [SCHEDULER] FCFS embed VM vm_379 -> PM PM_1 at t=115
[2025-12-19 10:21:20] [INFO] [STATE] VM vm_348 placed on PM PM_1
[2025-12-19 10:21:20] [INFO] [STATE] VM vm_349 placed on PM PM_1
[2025-12-19 10:21:20] [INFO] [STATE] VM vm_350 placed on PM PM_1
[2025-12-19 10:21:20] [INFO] [STATE] VM vm_351 placed on PM PM_1
[2025-12-19 10:21:20] [INFO] [STATE] VM vm_352 placed on PM PM_1
[2025-12-19 10:21:20] [INFO] [STATE] VM vm_353 placed on PM PM_1
[2025-12-19 10:21:20] [INFO] [STATE] VM vm_354 placed on PM PM_1
[2025-12-19 10:21:20] [INFO] [STATE] VM vm_355 placed on PM PM_1
[2025-12-19 10:21:20] [INFO] [STATE] VM vm_356 placed on PM PM_1
[2025-12-19 10:21:20] [INFO] [STATE] VM vm_357 placed on PM PM_1
[2025-12-19 10:21:20] [INFO] [STATE] VM vm_358 placed on PM PM_1
[2025-12-19 10:21:20] [INFO] [STATE] VM vm_359 placed on PM PM_1
[2025-12-19 10:21:20] [INFO] [STATE] VM vm_360 placed on PM PM_1
[2025-12-19 10:21:20] [INFO] [STATE] VM vm_361 placed on PM PM_1
[2025-12-19 10:21:20] [INFO] [STATE] VM vm_362 placed on PM PM_1
[2025-12-19 10:21:20] [INFO] [STATE] VM vm_363 placed on PM PM_1
[2025-12-19 10:21:20] [INFO] [STATE] VM vm_364 placed on PM PM_1
[2025-12-19 10:21:20] [INFO] [STATE] VM vm_365 placed on PM PM_1
[2025-12-19 10:21:20] [INFO] [STATE] VM vm_366 placed on PM PM_1
[2025-12-19 10:21:20] [INFO] [STATE] VM vm_367 placed on PM PM_1
[2025-12-19 10:21:20] [INFO] [STATE] VM vm_368 placed on PM PM_1
[2025-12-19 10:21:20] [INFO] [STATE] VM vm_369 placed on PM PM_1
[2025-12-19 10:21:20] [INFO] [STATE] VM vm_370 placed on PM PM_1
[2025-12-19 10:21:20] [INFO] [STATE] VM vm_371 placed on PM PM_1
[2025-12-19 10:21:20] [INFO] [STATE] VM vm_372 placed on PM PM_1
[2025-12-19 10:21:20] [INFO] [STATE] VM vm_373 placed on PM PM_1
[2025-12-19 10:21:20] [INFO] [STATE] VM vm_374 placed on PM PM_1
[2025-12-19 10:21:20] [INFO] [STATE] VM vm_375 placed on PM PM_1
[2025-12-19 10:21:20] [INFO] [STATE] VM vm_376 placed on PM PM_1
[2025-12-19 10:21:20] [INFO] [STATE] VM vm_377 placed on PM PM_1
[2025-12-19 10:21:20] [INFO] [STATE] VM vm_378 placed on PM PM_1
[2025-12-19 10:21:20] [INFO] [STATE] VM vm_379 placed on PM PM_1
[2025-12-19 10:21:20] [INFO] [VM_EVENT] VM vm_380 created (pending) at t=116
[2025-12-19 10:21:20] [INFO] [VM_EVENT] VM vm_381 created (pending) at t=116
[2025-12-19 10:21:20] [INFO] [VM_EVENT] VM vm_382 created (pending) at t=116
[2025-12-19 10:21:20] [INFO] [VM_EVENT] VM vm_383 created (pending) at t=116
[2025-12-19 10:21:20] [INFO] [VM_EVENT] VM vm_384 created (pending) at t=116
[2025-12-19 10:21:20] [INFO] [VM_EVENT] VM vm_385 created (pending) at t=116
[2025-12-19 10:21:20] [INFO] [VM_EVENT] VM vm_386 created (pending) at t=116
[2025-12-19 10:21:20] [INFO] [VM_EVENT] VM vm_387 created (pending) at t=116
[2025-12-19 10:21:20] [INFO] [VM_EVENT] VM vm_388 created (pending) at t=116
[2025-12-19 10:21:20] [INFO] [VM_EVENT] VM vm_389 created (pending) at t=116
[2025-12-19 10:21:20] [INFO] [VM_EVENT] VM vm_390 created (pending) at t=116
[2025-12-19 10:21:20] [INFO] [VM_EVENT] VM vm_391 created (pending) at t=116
[2025-12-19 10:21:20] [INFO] [VM_EVENT] VM vm_392 created (pending) at t=116
[2025-12-19 10:21:20] [INFO] [VM_EVENT] VM vm_393 created (pending) at t=116
[2025-12-19 10:21:20] [INFO] [VM_EVENT] VM vm_394 created (pending) at t=116
[2025-12-19 10:21:20] [INFO] [VM_EVENT] VM vm_395 created (pending) at t=116
[2025-12-19 10:21:20] [INFO] [VM_EVENT] VM vm_396 created (pending) at t=116
[2025-12-19 10:21:20] [INFO] [VM_EVENT] VM vm_397 created (pending) at t=116
[2025-12-19 10:21:20] [INFO] [VM_EVENT] VM vm_398 created (pending) at t=116
[2025-12-19 10:21:20] [INFO] [VM_EVENT] VM vm_399 created (pending) at t=116
[2025-12-19 10:21:20] [INFO] [VM_EVENT] VM vm_400 created (pending) at t=116
[2025-12-19 10:21:20] [INFO] [VM_EVENT] VM vm_401 created (pending) at t=116
[2025-12-19 10:21:20] [INFO] [VM_EVENT] VM vm_402 created (pending) at t=116
[2025-12-19 10:21:20] [INFO] [VM_EVENT] VM vm_403 created (pending) at t=116
[2025-12-19 10:21:20] [INFO] [VM_EVENT] VM vm_404 created (pending) at t=116
[2025-12-19 10:21:20] [INFO] [VM_EVENT] VM vm_405 created (pending) at t=116
[2025-12-19 10:21:20] [INFO] [VM_EVENT] VM vm_406 created (pending) at t=116
[2025-12-19 10:21:20] [INFO] [SCHEDULER] FCFS embed VM vm_380 -> PM PM_0 at t=116
[2025-12-19 10:21:20] [INFO] [SCHEDULER] FCFS embed VM vm_381 -> PM PM_0 at t=116
[2025-12-19 10:21:20] [INFO] [SCHEDULER] FCFS embed VM vm_382 -> PM PM_0 at t=116
[2025-12-19 10:21:20] [INFO] [SCHEDULER] FCFS embed VM vm_383 -> PM PM_0 at t=116
[2025-12-19 10:21:20] [INFO] [SCHEDULER] FCFS embed VM vm_384 -> PM PM_0 at t=116
[2025-12-19 10:21:20] [INFO] [SCHEDULER] FCFS embed VM vm_385 -> PM PM_0 at t=116
[2025-12-19 10:21:20] [INFO] [SCHEDULER] FCFS embed VM vm_386 -> PM PM_0 at t=116
[2025-12-19 10:21:20] [INFO] [SCHEDULER] FCFS embed VM vm_387 -> PM PM_0 at t=116
[2025-12-19 10:21:20] [INFO] [SCHEDULER] FCFS embed VM vm_388 -> PM PM_0 at t=116
[2025-12-19 10:21:20] [INFO] [SCHEDULER] FCFS embed VM vm_389 -> PM PM_0 at t=116
[2025-12-19 10:21:20] [INFO] [SCHEDULER] FCFS embed VM vm_390 -> PM PM_0 at t=116
[2025-12-19 10:21:20] [INFO] [SCHEDULER] FCFS embed VM vm_391 -> PM PM_0 at t=116
[2025-12-19 10:21:20] [INFO] [SCHEDULER] FCFS embed VM vm_392 -> PM PM_0 at t=116
[2025-12-19 10:21:20] [INFO] [SCHEDULER] FCFS embed VM vm_393 -> PM PM_0 at t=116
[2025-12-19 10:21:20] [INFO] [SCHEDULER] FCFS embed VM vm_394 -> PM PM_0 at t=116
[2025-12-19 10:21:20] [INFO] [SCHEDULER] FCFS embed VM vm_395 -> PM PM_0 at t=116
[2025-12-19 10:21:20] [INFO] [SCHEDULER] FCFS embed VM vm_396 -> PM PM_0 at t=116
[2025-12-19 10:21:20] [INFO] [SCHEDULER] FCFS embed VM vm_397 -> PM PM_0 at t=116
[2025-12-19 10:21:20] [INFO] [SCHEDULER] FCFS embed VM vm_398 -> PM PM_0 at t=116
[2025-12-19 10:21:20] [INFO] [SCHEDULER] FCFS embed VM vm_399 -> PM PM_0 at t=116
[2025-12-19 10:21:20] [INFO] [SCHEDULER] FCFS embed VM vm_400 -> PM PM_0 at t=116
[2025-12-19 10:21:20] [INFO] [SCHEDULER] FCFS embed VM vm_401 -> PM PM_0 at t=116
[2025-12-19 10:21:20] [INFO] [SCHEDULER] FCFS embed VM vm_402 -> PM PM_0 at t=116
[2025-12-19 10:21:20] [INFO] [SCHEDULER] FCFS embed VM vm_403 -> PM PM_0 at t=116
[2025-12-19 10:21:20] [INFO] [SCHEDULER] FCFS embed VM vm_404 -> PM PM_0 at t=116
[2025-12-19 10:21:20] [INFO] [SCHEDULER] FCFS embed VM vm_405 -> PM PM_0 at t=116
[2025-12-19 10:21:20] [INFO] [SCHEDULER] FCFS embed VM vm_406 -> PM PM_0 at t=116
[2025-12-19 10:21:20] [INFO] [STATE] VM vm_380 placed on PM PM_0
[2025-12-19 10:21:20] [INFO] [STATE] VM vm_381 placed on PM PM_0
[2025-12-19 10:21:20] [INFO] [STATE] VM vm_382 placed on PM PM_0
[2025-12-19 10:21:20] [INFO] [STATE] VM vm_383 placed on PM PM_0
[2025-12-19 10:21:20] [INFO] [STATE] VM vm_384 placed on PM PM_0
[2025-12-19 10:21:20] [INFO] [STATE] VM vm_385 placed on PM PM_0
[2025-12-19 10:21:20] [INFO] [STATE] VM vm_386 placed on PM PM_0
[2025-12-19 10:21:20] [INFO] [STATE] VM vm_387 placed on PM PM_0
[2025-12-19 10:21:20] [INFO] [STATE] VM vm_388 placed on PM PM_0
[2025-12-19 10:21:20] [INFO] [STATE] VM vm_389 placed on PM PM_0
[2025-12-19 10:21:20] [INFO] [STATE] VM vm_390 placed on PM PM_0
[2025-12-19 10:21:20] [INFO] [STATE] VM vm_391 placed on PM PM_0
[2025-12-19 10:21:20] [INFO] [STATE] VM vm_392 placed on PM PM_0
[2025-12-19 10:21:20] [INFO] [STATE] VM vm_393 placed on PM PM_0
[2025-12-19 10:21:20] [INFO] [STATE] VM vm_394 placed on PM PM_0
[2025-12-19 10:21:20] [INFO] [STATE] VM vm_395 placed on PM PM_0
[2025-12-19 10:21:20] [INFO] [STATE] VM vm_396 placed on PM PM_0
[2025-12-19 10:21:20] [INFO] [STATE] VM vm_397 placed on PM PM_0
[2025-12-19 10:21:20] [INFO] [STATE] VM vm_398 placed on PM PM_0
[2025-12-19 10:21:20] [INFO] [STATE] VM vm_399 placed on PM PM_0
[2025-12-19 10:21:20] [INFO] [STATE] VM vm_400 placed on PM PM_0
[2025-12-19 10:21:20] [INFO] [STATE] VM vm_401 placed on PM PM_0
[2025-12-19 10:21:20] [INFO] [STATE] VM vm_402 placed on PM PM_0
[2025-12-19 10:21:20] [INFO] [STATE] VM vm_403 placed on PM PM_0
[2025-12-19 10:21:20] [INFO] [STATE] VM vm_404 placed on PM PM_0
[2025-12-19 10:21:20] [INFO] [STATE] VM vm_405 placed on PM PM_0
[2025-12-19 10:21:20] [INFO] [STATE] VM vm_406 placed on PM PM_0
[2025-12-19 10:21:20] [INFO] [VM_EVENT] VM vm_407 created (pending) at t=117
[2025-12-19 10:21:20] [INFO] [VM_EVENT] VM vm_408 created (pending) at t=117
[2025-12-19 10:21:20] [INFO] [VM_EVENT] VM vm_409 created (pending) at t=117
[2025-12-19 10:21:20] [INFO] [VM_EVENT] VM vm_410 created (pending) at t=117
[2025-12-19 10:21:20] [INFO] [VM_EVENT] VM vm_411 created (pending) at t=117
[2025-12-19 10:21:20] [INFO] [VM_EVENT] VM vm_412 created (pending) at t=117
[2025-12-19 10:21:20] [INFO] [VM_EVENT] VM vm_413 created (pending) at t=117
[2025-12-19 10:21:20] [INFO] [VM_EVENT] VM vm_414 created (pending) at t=117
[2025-12-19 10:21:20] [INFO] [VM_EVENT] VM vm_415 created (pending) at t=117
[2025-12-19 10:21:20] [INFO] [VM_EVENT] VM vm_416 created (pending) at t=117
[2025-12-19 10:21:20] [INFO] [VM_EVENT] VM vm_417 created (pending) at t=117
[2025-12-19 10:21:20] [INFO] [VM_EVENT] VM vm_418 created (pending) at t=117
[2025-12-19 10:21:20] [INFO] [VM_EVENT] VM vm_419 created (pending) at t=117
[2025-12-19 10:21:20] [INFO] [VM_EVENT] VM vm_420 created (pending) at t=117
[2025-12-19 10:21:20] [INFO] [VM_EVENT] VM vm_421 created (pending) at t=117
[2025-12-19 10:21:20] [INFO] [VM_EVENT] VM vm_422 created (pending) at t=117
[2025-12-19 10:21:20] [INFO] [VM_EVENT] VM vm_423 created (pending) at t=117
[2025-12-19 10:21:20] [INFO] [VM_EVENT] VM vm_424 created (pending) at t=117
[2025-12-19 10:21:20] [INFO] [VM_EVENT] VM vm_425 created (pending) at t=117
[2025-12-19 10:21:20] [INFO] [SCHEDULER] FCFS embed VM vm_407 -> PM PM_6 at t=117
[2025-12-19 10:21:20] [INFO] [SCHEDULER] FCFS embed VM vm_408 -> PM PM_6 at t=117
[2025-12-19 10:21:20] [INFO] [SCHEDULER] FCFS embed VM vm_409 -> PM PM_6 at t=117
[2025-12-19 10:21:20] [INFO] [SCHEDULER] FCFS embed VM vm_410 -> PM PM_6 at t=117
[2025-12-19 10:21:20] [INFO] [SCHEDULER] FCFS embed VM vm_411 -> PM PM_6 at t=117
[2025-12-19 10:21:20] [INFO] [SCHEDULER] FCFS embed VM vm_412 -> PM PM_6 at t=117
[2025-12-19 10:21:20] [INFO] [SCHEDULER] FCFS embed VM vm_413 -> PM PM_6 at t=117
[2025-12-19 10:21:20] [INFO] [SCHEDULER] FCFS embed VM vm_414 -> PM PM_6 at t=117
[2025-12-19 10:21:20] [INFO] [SCHEDULER] FCFS embed VM vm_415 -> PM PM_6 at t=117
[2025-12-19 10:21:20] [INFO] [SCHEDULER] FCFS embed VM vm_416 -> PM PM_6 at t=117
[2025-12-19 10:21:20] [INFO] [SCHEDULER] FCFS embed VM vm_417 -> PM PM_6 at t=117
[2025-12-19 10:21:20] [INFO] [SCHEDULER] FCFS embed VM vm_418 -> PM PM_6 at t=117
[2025-12-19 10:21:20] [INFO] [SCHEDULER] FCFS embed VM vm_419 -> PM PM_6 at t=117
[2025-12-19 10:21:20] [INFO] [SCHEDULER] FCFS embed VM vm_420 -> PM PM_6 at t=117
[2025-12-19 10:21:20] [INFO] [SCHEDULER] FCFS embed VM vm_421 -> PM PM_6 at t=117
[2025-12-19 10:21:20] [INFO] [SCHEDULER] FCFS embed VM vm_422 -> PM PM_6 at t=117
[2025-12-19 10:21:20] [INFO] [SCHEDULER] FCFS embed VM vm_423 -> PM PM_6 at t=117
[2025-12-19 10:21:20] [INFO] [SCHEDULER] FCFS embed VM vm_424 -> PM PM_6 at t=117
[2025-12-19 10:21:20] [INFO] [SCHEDULER] FCFS embed VM vm_425 -> PM PM_6 at t=117
[2025-12-19 10:21:20] [INFO] [STATE] VM vm_407 placed on PM PM_6
[2025-12-19 10:21:20] [INFO] [STATE] VM vm_408 placed on PM PM_6
[2025-12-19 10:21:20] [INFO] [STATE] VM vm_409 placed on PM PM_6
[2025-12-19 10:21:20] [INFO] [STATE] VM vm_410 placed on PM PM_6
[2025-12-19 10:21:20] [INFO] [STATE] VM vm_411 placed on PM PM_6
[2025-12-19 10:21:20] [INFO] [STATE] VM vm_412 placed on PM PM_6
[2025-12-19 10:21:20] [INFO] [STATE] VM vm_413 placed on PM PM_6
[2025-12-19 10:21:20] [INFO] [STATE] VM vm_414 placed on PM PM_6
[2025-12-19 10:21:20] [INFO] [STATE] VM vm_415 placed on PM PM_6
[2025-12-19 10:21:20] [INFO] [STATE] VM vm_416 placed on PM PM_6
[2025-12-19 10:21:20] [INFO] [STATE] VM vm_417 placed on PM PM_6
[2025-12-19 10:21:20] [INFO] [STATE] VM vm_418 placed on PM PM_6
[2025-12-19 10:21:20] [INFO] [STATE] VM vm_419 placed on PM PM_6
[2025-12-19 10:21:20] [INFO] [STATE] VM vm_420 placed on PM PM_6
[2025-12-19 10:21:20] [INFO] [STATE] VM vm_421 placed on PM PM_6
[2025-12-19 10:21:20] [INFO] [STATE] VM vm_422 placed on PM PM_6
[2025-12-19 10:21:20] [INFO] [STATE] VM vm_423 placed on PM PM_6
[2025-12-19 10:21:20] [INFO] [STATE] VM vm_424 placed on PM PM_6
[2025-12-19 10:21:20] [INFO] [STATE] VM vm_425 placed on PM PM_6
[2025-12-19 10:21:20] [INFO] [VM_EVENT] VM vm_426 created (pending) at t=118
[2025-12-19 10:21:20] [INFO] [VM_EVENT] VM vm_427 created (pending) at t=118
[2025-12-19 10:21:20] [INFO] [VM_EVENT] VM vm_428 created (pending) at t=118
[2025-12-19 10:21:20] [INFO] [VM_EVENT] VM vm_429 created (pending) at t=118
[2025-12-19 10:21:20] [INFO] [VM_EVENT] VM vm_430 created (pending) at t=118
[2025-12-19 10:21:20] [INFO] [VM_EVENT] VM vm_431 created (pending) at t=118
[2025-12-19 10:21:20] [INFO] [VM_EVENT] VM vm_432 created (pending) at t=118
[2025-12-19 10:21:20] [INFO] [VM_EVENT] VM vm_433 created (pending) at t=118
[2025-12-19 10:21:20] [INFO] [VM_EVENT] VM vm_434 created (pending) at t=118
[2025-12-19 10:21:20] [INFO] [VM_EVENT] VM vm_435 created (pending) at t=118
[2025-12-19 10:21:20] [INFO] [VM_EVENT] VM vm_436 created (pending) at t=118
[2025-12-19 10:21:20] [INFO] [VM_EVENT] VM vm_437 created (pending) at t=118
[2025-12-19 10:21:20] [INFO] [VM_EVENT] VM vm_438 created (pending) at t=118
[2025-12-19 10:21:20] [INFO] [VM_EVENT] VM vm_439 created (pending) at t=118
[2025-12-19 10:21:20] [INFO] [VM_EVENT] VM vm_440 created (pending) at t=118
[2025-12-19 10:21:20] [INFO] [VM_EVENT] VM vm_441 created (pending) at t=118
[2025-12-19 10:21:20] [INFO] [VM_EVENT] VM vm_442 created (pending) at t=118
[2025-12-19 10:21:20] [INFO] [VM_EVENT] VM vm_443 created (pending) at t=118
[2025-12-19 10:21:20] [INFO] [VM_EVENT] VM vm_444 created (pending) at t=118
[2025-12-19 10:21:20] [INFO] [VM_EVENT] VM vm_445 created (pending) at t=118
[2025-12-19 10:21:20] [INFO] [VM_EVENT] VM vm_446 created (pending) at t=118
[2025-12-19 10:21:20] [INFO] [VM_EVENT] VM vm_447 created (pending) at t=118
[2025-12-19 10:21:20] [INFO] [VM_EVENT] VM vm_448 created (pending) at t=118
[2025-12-19 10:21:20] [INFO] [VM_EVENT] VM vm_449 created (pending) at t=118
[2025-12-19 10:21:20] [INFO] [SCHEDULER] FCFS embed VM vm_426 -> PM PM_7 at t=118
[2025-12-19 10:21:20] [INFO] [SCHEDULER] FCFS embed VM vm_427 -> PM PM_7 at t=118
[2025-12-19 10:21:20] [INFO] [SCHEDULER] FCFS embed VM vm_428 -> PM PM_7 at t=118
[2025-12-19 10:21:20] [INFO] [SCHEDULER] FCFS embed VM vm_429 -> PM PM_7 at t=118
[2025-12-19 10:21:20] [INFO] [SCHEDULER] FCFS embed VM vm_430 -> PM PM_7 at t=118
[2025-12-19 10:21:20] [INFO] [SCHEDULER] FCFS embed VM vm_431 -> PM PM_7 at t=118
[2025-12-19 10:21:20] [INFO] [SCHEDULER] FCFS embed VM vm_432 -> PM PM_7 at t=118
[2025-12-19 10:21:20] [INFO] [SCHEDULER] FCFS embed VM vm_433 -> PM PM_7 at t=118
[2025-12-19 10:21:20] [INFO] [SCHEDULER] FCFS embed VM vm_434 -> PM PM_7 at t=118
[2025-12-19 10:21:20] [INFO] [SCHEDULER] FCFS embed VM vm_435 -> PM PM_7 at t=118
[2025-12-19 10:21:20] [INFO] [SCHEDULER] FCFS embed VM vm_436 -> PM PM_7 at t=118
[2025-12-19 10:21:20] [INFO] [SCHEDULER] FCFS embed VM vm_437 -> PM PM_7 at t=118
[2025-12-19 10:21:20] [INFO] [SCHEDULER] FCFS embed VM vm_438 -> PM PM_7 at t=118
[2025-12-19 10:21:20] [INFO] [SCHEDULER] FCFS embed VM vm_439 -> PM PM_7 at t=118
[2025-12-19 10:21:20] [INFO] [SCHEDULER] FCFS embed VM vm_440 -> PM PM_7 at t=118
[2025-12-19 10:21:20] [INFO] [SCHEDULER] FCFS embed VM vm_441 -> PM PM_7 at t=118
[2025-12-19 10:21:20] [INFO] [SCHEDULER] FCFS embed VM vm_442 -> PM PM_7 at t=118
[2025-12-19 10:21:20] [INFO] [SCHEDULER] FCFS embed VM vm_443 -> PM PM_7 at t=118
[2025-12-19 10:21:20] [INFO] [SCHEDULER] FCFS embed VM vm_444 -> PM PM_7 at t=118
[2025-12-19 10:21:20] [INFO] [SCHEDULER] FCFS embed VM vm_445 -> PM PM_7 at t=118
